<<<<<<< HEAD
2017-11-28 16:20:54,879:WARNING:Not Found: /admin/a
2017-11-28 16:54:53,721:INFO:request course list for dashboard
2017-11-28 16:54:55,891:WARNING:Not Found: /dashboard/lai shi shi kan
2017-11-28 16:57:56,331:INFO:request course list for dashboard
2017-11-28 16:57:58,453:WARNING:request course detail failed: course code = COMP1111
2017-11-28 16:57:58,891:INFO:request course list for dashboard
2017-11-28 16:58:01,470:WARNING:request course detail failed: course code = COMP1111
2017-11-28 16:58:01,830:INFO:request course list for dashboard
2017-11-28 16:58:08,349:WARNING:request course detail failed: course code = COMP1111
2017-11-28 16:58:08,705:INFO:request course list for dashboard
2017-11-28 17:00:10,951:INFO:request course list for dashboard
2017-11-28 17:00:12,870:WARNING:request course detail failed: course code = COMP1111
2017-11-28 17:00:13,222:INFO:request course list for dashboard
2017-11-28 17:02:45,568:WARNING:request course detail failed: course code = COMP1111
2017-11-28 17:02:45,988:INFO:request course list for dashboard
2017-11-28 17:02:51,724:WARNING:Not Found: /dashboard/coursedetails.html
2017-11-28 17:03:39,126:WARNING:request course detail failed: course code = COMP1111
2017-11-28 17:03:39,478:INFO:request course list for dashboard
2017-11-28 17:03:40,075:WARNING:request course detail failed: course code = COMP1111
2017-11-28 17:03:40,433:INFO:request course list for dashboard
2017-11-28 17:03:42,761:WARNING:request course detail failed: course code = COMP1111
2017-11-28 17:03:42,927:WARNING:request course detail failed: course code = COMP1111
2017-11-28 17:03:43,071:WARNING:request course detail failed: course code = COMP1111
2017-11-28 17:03:43,211:WARNING:request course detail failed: course code = COMP1111
2017-11-28 17:03:43,437:WARNING:request course detail failed: course code = COMP1111
2017-11-28 17:03:43,805:INFO:request course list for dashboard
2017-11-28 17:05:08,205:WARNING:request course detail failed: course code = COMP1111
2017-11-28 17:05:08,573:WARNING:request course detail failed: course code = COMP1111
2017-11-28 17:05:08,925:INFO:request course list for dashboard
2017-11-28 17:05:26,308:WARNING:request course detail failed: course code = COMP1111
2017-11-28 17:05:26,661:INFO:request course list for dashboard
2017-11-28 17:09:19,789:WARNING:request course detail failed: course code = COMP1111
2017-11-28 17:09:20,143:INFO:request course list for dashboard
2017-11-28 17:10:05,424:WARNING:request course detail failed: course code = COMP1111
2017-11-28 17:10:05,786:INFO:request course list for dashboard
2017-11-28 17:10:08,270:WARNING:request course detail failed: course code = COMP1111
2017-11-28 17:10:08,622:INFO:request course list for dashboard
2017-11-28 17:15:25,574:INFO:request course list for dashboard
2017-11-28 17:15:27,581:WARNING:request course detail failed: course code = COMP1111
2017-11-28 17:15:27,917:INFO:request course list for dashboard
2017-11-28 17:15:29,769:WARNING:request course detail failed: course code = COMP1111
2017-11-28 17:15:30,123:INFO:request course list for dashboard
2017-11-28 17:15:40,015:INFO:request course list for dashboard
2017-11-28 17:15:41,490:WARNING:request course detail failed: course code = COMP1111
2017-11-28 17:15:41,855:INFO:request course list for dashboard
2017-11-28 17:17:31,300:INFO:request course list for dashboard
2017-11-28 17:17:44,383:INFO:request course list for dashboard
2017-11-28 17:17:46,460:WARNING:request course detail failed: course code = COMP1111
2017-11-28 17:17:46,808:INFO:request course list for dashboard
2017-11-28 17:28:12,265:WARNING:request course detail failed: course code = COMP1111
2017-11-28 17:28:12,625:INFO:request course list for dashboard
2017-11-28 17:28:14,691:INFO:request course list for dashboard
2017-11-28 17:28:16,760:WARNING:request course detail failed: course code = COMP1111
2017-11-28 17:28:17,094:INFO:request course list for dashboard
2017-11-28 17:42:58,157:ERROR:Internal Server Error: /account/auth
Traceback (most recent call last):
  File "/home/ivan/.local/lib/python3.6/site-packages/django/db/backends/base/base.py", line 213, in ensure_connection
    self.connect()
  File "/home/ivan/.local/lib/python3.6/site-packages/django/db/backends/base/base.py", line 189, in connect
    self.connection = self.get_new_connection(conn_params)
  File "/home/ivan/.local/lib/python3.6/site-packages/django/db/backends/mysql/base.py", line 274, in get_new_connection
    conn = Database.connect(**conn_params)
  File "/home/ivan/.local/lib/python3.6/site-packages/MySQLdb/__init__.py", line 86, in Connect
    return Connection(*args, **kwargs)
  File "/home/ivan/.local/lib/python3.6/site-packages/MySQLdb/connections.py", line 204, in __init__
    super(Connection, self).__init__(*args, **kwargs2)
_mysql_exceptions.OperationalError: (2003, "Can't connect to MySQL server on '128.199.130.241' (111)")

The above exception was the direct cause of the following exception:

Traceback (most recent call last):
  File "/home/ivan/.local/lib/python3.6/site-packages/django/core/handlers/exception.py", line 41, in inner
    response = get_response(request)
  File "/home/ivan/.local/lib/python3.6/site-packages/django/core/handlers/base.py", line 187, in _get_response
    response = self.process_exception_by_middleware(e, request)
  File "/home/ivan/.local/lib/python3.6/site-packages/django/core/handlers/base.py", line 185, in _get_response
    response = wrapped_callback(request, *callback_args, **callback_kwargs)
  File "/home/ivan/.local/lib/python3.6/site-packages/django/views/decorators/csrf.py", line 58, in wrapped_view
    return view_func(*args, **kwargs)
  File "/home/ivan/dbs-proj/comp3335/account/views.py", line 96, in auth
    for acct in accts:
  File "/home/ivan/.local/lib/python3.6/site-packages/django/db/models/query.py", line 250, in __iter__
    self._fetch_all()
  File "/home/ivan/.local/lib/python3.6/site-packages/django/db/models/query.py", line 1118, in _fetch_all
    self._result_cache = list(self._iterable_class(self))
  File "/home/ivan/.local/lib/python3.6/site-packages/django/db/models/query.py", line 53, in __iter__
    results = compiler.execute_sql(chunked_fetch=self.chunked_fetch)
  File "/home/ivan/.local/lib/python3.6/site-packages/django/db/models/sql/compiler.py", line 882, in execute_sql
    cursor = self.connection.cursor()
  File "/home/ivan/.local/lib/python3.6/site-packages/django/db/backends/base/base.py", line 254, in cursor
    return self._cursor()
  File "/home/ivan/.local/lib/python3.6/site-packages/django/db/backends/base/base.py", line 229, in _cursor
    self.ensure_connection()
  File "/home/ivan/.local/lib/python3.6/site-packages/django/db/backends/base/base.py", line 213, in ensure_connection
    self.connect()
  File "/home/ivan/.local/lib/python3.6/site-packages/django/db/utils.py", line 94, in __exit__
    six.reraise(dj_exc_type, dj_exc_value, traceback)
  File "/home/ivan/.local/lib/python3.6/site-packages/django/utils/six.py", line 685, in reraise
    raise value.with_traceback(tb)
  File "/home/ivan/.local/lib/python3.6/site-packages/django/db/backends/base/base.py", line 213, in ensure_connection
    self.connect()
  File "/home/ivan/.local/lib/python3.6/site-packages/django/db/backends/base/base.py", line 189, in connect
    self.connection = self.get_new_connection(conn_params)
  File "/home/ivan/.local/lib/python3.6/site-packages/django/db/backends/mysql/base.py", line 274, in get_new_connection
    conn = Database.connect(**conn_params)
  File "/home/ivan/.local/lib/python3.6/site-packages/MySQLdb/__init__.py", line 86, in Connect
    return Connection(*args, **kwargs)
  File "/home/ivan/.local/lib/python3.6/site-packages/MySQLdb/connections.py", line 204, in __init__
    super(Connection, self).__init__(*args, **kwargs2)
django.db.utils.OperationalError: (2003, "Can't connect to MySQL server on '128.199.130.241' (111)")
2017-11-28 17:43:11,861:ERROR:Internal Server Error: /account/auth
Traceback (most recent call last):
  File "/home/ivan/.local/lib/python3.6/site-packages/django/db/backends/base/base.py", line 213, in ensure_connection
    self.connect()
  File "/home/ivan/.local/lib/python3.6/site-packages/django/db/backends/base/base.py", line 189, in connect
    self.connection = self.get_new_connection(conn_params)
  File "/home/ivan/.local/lib/python3.6/site-packages/django/db/backends/mysql/base.py", line 274, in get_new_connection
    conn = Database.connect(**conn_params)
  File "/home/ivan/.local/lib/python3.6/site-packages/MySQLdb/__init__.py", line 86, in Connect
    return Connection(*args, **kwargs)
  File "/home/ivan/.local/lib/python3.6/site-packages/MySQLdb/connections.py", line 204, in __init__
    super(Connection, self).__init__(*args, **kwargs2)
_mysql_exceptions.OperationalError: (2003, "Can't connect to MySQL server on '128.199.130.241' (111)")

The above exception was the direct cause of the following exception:

Traceback (most recent call last):
  File "/home/ivan/.local/lib/python3.6/site-packages/django/core/handlers/exception.py", line 41, in inner
    response = get_response(request)
  File "/home/ivan/.local/lib/python3.6/site-packages/django/core/handlers/base.py", line 187, in _get_response
    response = self.process_exception_by_middleware(e, request)
  File "/home/ivan/.local/lib/python3.6/site-packages/django/core/handlers/base.py", line 185, in _get_response
    response = wrapped_callback(request, *callback_args, **callback_kwargs)
  File "/home/ivan/.local/lib/python3.6/site-packages/django/views/decorators/csrf.py", line 58, in wrapped_view
    return view_func(*args, **kwargs)
  File "/home/ivan/dbs-proj/comp3335/account/views.py", line 96, in auth
    for acct in accts:
  File "/home/ivan/.local/lib/python3.6/site-packages/django/db/models/query.py", line 250, in __iter__
    self._fetch_all()
  File "/home/ivan/.local/lib/python3.6/site-packages/django/db/models/query.py", line 1118, in _fetch_all
    self._result_cache = list(self._iterable_class(self))
  File "/home/ivan/.local/lib/python3.6/site-packages/django/db/models/query.py", line 53, in __iter__
    results = compiler.execute_sql(chunked_fetch=self.chunked_fetch)
  File "/home/ivan/.local/lib/python3.6/site-packages/django/db/models/sql/compiler.py", line 882, in execute_sql
    cursor = self.connection.cursor()
  File "/home/ivan/.local/lib/python3.6/site-packages/django/db/backends/base/base.py", line 254, in cursor
    return self._cursor()
  File "/home/ivan/.local/lib/python3.6/site-packages/django/db/backends/base/base.py", line 229, in _cursor
    self.ensure_connection()
  File "/home/ivan/.local/lib/python3.6/site-packages/django/db/backends/base/base.py", line 213, in ensure_connection
    self.connect()
  File "/home/ivan/.local/lib/python3.6/site-packages/django/db/utils.py", line 94, in __exit__
    six.reraise(dj_exc_type, dj_exc_value, traceback)
  File "/home/ivan/.local/lib/python3.6/site-packages/django/utils/six.py", line 685, in reraise
    raise value.with_traceback(tb)
  File "/home/ivan/.local/lib/python3.6/site-packages/django/db/backends/base/base.py", line 213, in ensure_connection
    self.connect()
  File "/home/ivan/.local/lib/python3.6/site-packages/django/db/backends/base/base.py", line 189, in connect
    self.connection = self.get_new_connection(conn_params)
  File "/home/ivan/.local/lib/python3.6/site-packages/django/db/backends/mysql/base.py", line 274, in get_new_connection
    conn = Database.connect(**conn_params)
  File "/home/ivan/.local/lib/python3.6/site-packages/MySQLdb/__init__.py", line 86, in Connect
    return Connection(*args, **kwargs)
  File "/home/ivan/.local/lib/python3.6/site-packages/MySQLdb/connections.py", line 204, in __init__
    super(Connection, self).__init__(*args, **kwargs2)
django.db.utils.OperationalError: (2003, "Can't connect to MySQL server on '128.199.130.241' (110)")
2017-11-28 15:01:22,108:INFO:request course list for dashboard
2017-11-28 15:01:24,104:INFO:request course list for dashboard
2017-11-28 15:01:26,167:INFO:request course list for dashboard
2017-11-28 15:02:43,420:INFO:request course list for dashboard
2017-11-28 15:02:48,678:INFO:request course list for dashboard
2017-11-28 15:22:44,414:ERROR:Internal Server Error: /admin/course/course/
Traceback (most recent call last):
  File "/home/xiating/.local/lib/python3.5/site-packages/django/db/models/options.py", line 617, in get_field
    return self.fields_map[field_name]
KeyError: '__str__'

During handling of the above exception, another exception occurred:

Traceback (most recent call last):
  File "/home/xiating/.local/lib/python3.5/site-packages/django/contrib/admin/utils.py", line 283, in lookup_field
    f = _get_non_gfk_field(opts, name)
  File "/home/xiating/.local/lib/python3.5/site-packages/django/contrib/admin/utils.py", line 317, in _get_non_gfk_field
    field = opts.get_field(name)
  File "/home/xiating/.local/lib/python3.5/site-packages/django/db/models/options.py", line 619, in get_field
    raise FieldDoesNotExist("%s has no field named '%s'" % (self.object_name, field_name))
django.core.exceptions.FieldDoesNotExist: Course has no field named '__str__'

During handling of the above exception, another exception occurred:

Traceback (most recent call last):
  File "/home/xiating/.local/lib/python3.5/site-packages/django/core/handlers/exception.py", line 41, in inner
    response = get_response(request)
  File "/home/xiating/.local/lib/python3.5/site-packages/django/core/handlers/base.py", line 217, in _get_response
    response = self.process_exception_by_middleware(e, request)
  File "/home/xiating/.local/lib/python3.5/site-packages/django/core/handlers/base.py", line 215, in _get_response
    response = response.render()
  File "/home/xiating/.local/lib/python3.5/site-packages/django/template/response.py", line 107, in render
    self.content = self.rendered_content
  File "/home/xiating/.local/lib/python3.5/site-packages/django/template/response.py", line 84, in rendered_content
    content = template.render(context, self._request)
  File "/home/xiating/.local/lib/python3.5/site-packages/django/template/backends/django.py", line 66, in render
    return self.template.render(context)
  File "/home/xiating/.local/lib/python3.5/site-packages/django/template/base.py", line 207, in render
    return self._render(context)
  File "/home/xiating/.local/lib/python3.5/site-packages/django/template/base.py", line 199, in _render
    return self.nodelist.render(context)
  File "/home/xiating/.local/lib/python3.5/site-packages/django/template/base.py", line 990, in render
    bit = node.render_annotated(context)
  File "/home/xiating/.local/lib/python3.5/site-packages/django/template/base.py", line 957, in render_annotated
    return self.render(context)
  File "/home/xiating/.local/lib/python3.5/site-packages/django/template/loader_tags.py", line 177, in render
    return compiled_parent._render(context)
  File "/home/xiating/.local/lib/python3.5/site-packages/django/template/base.py", line 199, in _render
    return self.nodelist.render(context)
  File "/home/xiating/.local/lib/python3.5/site-packages/django/template/base.py", line 990, in render
    bit = node.render_annotated(context)
  File "/home/xiating/.local/lib/python3.5/site-packages/django/template/base.py", line 957, in render_annotated
    return self.render(context)
  File "/home/xiating/.local/lib/python3.5/site-packages/django/template/loader_tags.py", line 177, in render
    return compiled_parent._render(context)
  File "/home/xiating/.local/lib/python3.5/site-packages/django/template/base.py", line 199, in _render
    return self.nodelist.render(context)
  File "/home/xiating/.local/lib/python3.5/site-packages/django/template/base.py", line 990, in render
    bit = node.render_annotated(context)
  File "/home/xiating/.local/lib/python3.5/site-packages/django/template/base.py", line 957, in render_annotated
    return self.render(context)
  File "/home/xiating/.local/lib/python3.5/site-packages/django/template/loader_tags.py", line 72, in render
    result = block.nodelist.render(context)
  File "/home/xiating/.local/lib/python3.5/site-packages/django/template/base.py", line 990, in render
    bit = node.render_annotated(context)
  File "/home/xiating/.local/lib/python3.5/site-packages/django/template/base.py", line 957, in render_annotated
    return self.render(context)
  File "/home/xiating/.local/lib/python3.5/site-packages/django/template/loader_tags.py", line 72, in render
    result = block.nodelist.render(context)
  File "/home/xiating/.local/lib/python3.5/site-packages/django/template/base.py", line 990, in render
    bit = node.render_annotated(context)
  File "/home/xiating/.local/lib/python3.5/site-packages/django/template/base.py", line 957, in render_annotated
    return self.render(context)
  File "/home/xiating/.local/lib/python3.5/site-packages/django/template/library.py", line 225, in render
    _dict = self.func(*resolved_args, **resolved_kwargs)
  File "/home/xiating/.local/lib/python3.5/site-packages/django/contrib/admin/templatetags/admin_list.py", line 340, in result_list
    'results': list(results(cl))}
  File "/home/xiating/.local/lib/python3.5/site-packages/django/contrib/admin/templatetags/admin_list.py", line 316, in results
    yield ResultList(None, items_for_result(cl, res, None))
  File "/home/xiating/.local/lib/python3.5/site-packages/django/contrib/admin/templatetags/admin_list.py", line 307, in __init__
    super(ResultList, self).__init__(*items)
  File "/home/xiating/.local/lib/python3.5/site-packages/django/contrib/admin/templatetags/admin_list.py", line 218, in items_for_result
    f, attr, value = lookup_field(field_name, result, cl.model_admin)
  File "/home/xiating/.local/lib/python3.5/site-packages/django/contrib/admin/utils.py", line 299, in lookup_field
    value = attr()
  File "/home/xiating/dbsec/comp3335_project/comp3335/course/models.py", line 10, in __str__
    return msg_decrypt(self.code) + " "+ msg_decrypt(self.name)
NameError: name 'msg_decrypt' is not defined
2017-11-28 16:07:23,998:ERROR:Internal Server Error: /admin/course/course/add/
Traceback (most recent call last):
  File "/home/xiating/.local/lib/python3.5/site-packages/django/db/backends/utils.py", line 65, in execute
    return self.cursor.execute(sql, params)
  File "/home/xiating/.local/lib/python3.5/site-packages/django/db/backends/mysql/base.py", line 101, in execute
    return self.cursor.execute(query, args)
  File "/home/xiating/.local/lib/python3.5/site-packages/MySQLdb/cursors.py", line 250, in execute
    self.errorhandler(self, exc, value)
  File "/home/xiating/.local/lib/python3.5/site-packages/MySQLdb/connections.py", line 50, in defaulterrorhandler
    raise errorvalue
  File "/home/xiating/.local/lib/python3.5/site-packages/MySQLdb/cursors.py", line 247, in execute
    res = self._query(query)
  File "/home/xiating/.local/lib/python3.5/site-packages/MySQLdb/cursors.py", line 411, in _query
    rowcount = self._do_query(q)
  File "/home/xiating/.local/lib/python3.5/site-packages/MySQLdb/cursors.py", line 374, in _do_query
    db.query(q)
  File "/home/xiating/.local/lib/python3.5/site-packages/MySQLdb/connections.py", line 277, in query
    _mysql.connection.query(self, query)
_mysql_exceptions.DataError: (1406, "Data too long for column 'code' at row 1")

The above exception was the direct cause of the following exception:

Traceback (most recent call last):
  File "/home/xiating/.local/lib/python3.5/site-packages/django/core/handlers/exception.py", line 41, in inner
    response = get_response(request)
  File "/home/xiating/.local/lib/python3.5/site-packages/django/core/handlers/base.py", line 187, in _get_response
    response = self.process_exception_by_middleware(e, request)
  File "/home/xiating/.local/lib/python3.5/site-packages/django/core/handlers/base.py", line 185, in _get_response
    response = wrapped_callback(request, *callback_args, **callback_kwargs)
  File "/home/xiating/.local/lib/python3.5/site-packages/django/contrib/admin/options.py", line 551, in wrapper
    return self.admin_site.admin_view(view)(*args, **kwargs)
  File "/home/xiating/.local/lib/python3.5/site-packages/django/utils/decorators.py", line 149, in _wrapped_view
    response = view_func(request, *args, **kwargs)
  File "/home/xiating/.local/lib/python3.5/site-packages/django/views/decorators/cache.py", line 57, in _wrapped_view_func
    response = view_func(request, *args, **kwargs)
  File "/home/xiating/.local/lib/python3.5/site-packages/django/contrib/admin/sites.py", line 224, in inner
    return view(request, *args, **kwargs)
  File "/home/xiating/.local/lib/python3.5/site-packages/django/contrib/admin/options.py", line 1508, in add_view
    return self.changeform_view(request, None, form_url, extra_context)
  File "/home/xiating/.local/lib/python3.5/site-packages/django/utils/decorators.py", line 67, in _wrapper
    return bound_func(*args, **kwargs)
  File "/home/xiating/.local/lib/python3.5/site-packages/django/utils/decorators.py", line 149, in _wrapped_view
    response = view_func(request, *args, **kwargs)
  File "/home/xiating/.local/lib/python3.5/site-packages/django/utils/decorators.py", line 63, in bound_func
    return func.__get__(self, type(self))(*args2, **kwargs2)
  File "/home/xiating/.local/lib/python3.5/site-packages/django/contrib/admin/options.py", line 1408, in changeform_view
    return self._changeform_view(request, object_id, form_url, extra_context)
  File "/home/xiating/.local/lib/python3.5/site-packages/django/contrib/admin/options.py", line 1448, in _changeform_view
    self.save_model(request, new_object, form, not add)
  File "/home/xiating/dbsec/comp3335_project/comp3335/course/admin.py", line 16, in save_model
    obj.save()
  File "/home/xiating/.local/lib/python3.5/site-packages/django/db/models/base.py", line 808, in save
    force_update=force_update, update_fields=update_fields)
  File "/home/xiating/.local/lib/python3.5/site-packages/django/db/models/base.py", line 838, in save_base
    updated = self._save_table(raw, cls, force_insert, force_update, using, update_fields)
  File "/home/xiating/.local/lib/python3.5/site-packages/django/db/models/base.py", line 924, in _save_table
    result = self._do_insert(cls._base_manager, using, fields, update_pk, raw)
  File "/home/xiating/.local/lib/python3.5/site-packages/django/db/models/base.py", line 963, in _do_insert
    using=using, raw=raw)
  File "/home/xiating/.local/lib/python3.5/site-packages/django/db/models/manager.py", line 85, in manager_method
    return getattr(self.get_queryset(), name)(*args, **kwargs)
  File "/home/xiating/.local/lib/python3.5/site-packages/django/db/models/query.py", line 1076, in _insert
    return query.get_compiler(using=using).execute_sql(return_id)
  File "/home/xiating/.local/lib/python3.5/site-packages/django/db/models/sql/compiler.py", line 1107, in execute_sql
    cursor.execute(sql, params)
  File "/home/xiating/.local/lib/python3.5/site-packages/django/db/backends/utils.py", line 80, in execute
    return super(CursorDebugWrapper, self).execute(sql, params)
  File "/home/xiating/.local/lib/python3.5/site-packages/django/db/backends/utils.py", line 65, in execute
    return self.cursor.execute(sql, params)
  File "/home/xiating/.local/lib/python3.5/site-packages/django/db/utils.py", line 94, in __exit__
    six.reraise(dj_exc_type, dj_exc_value, traceback)
  File "/home/xiating/.local/lib/python3.5/site-packages/django/utils/six.py", line 685, in reraise
    raise value.with_traceback(tb)
  File "/home/xiating/.local/lib/python3.5/site-packages/django/db/backends/utils.py", line 65, in execute
    return self.cursor.execute(sql, params)
  File "/home/xiating/.local/lib/python3.5/site-packages/django/db/backends/mysql/base.py", line 101, in execute
    return self.cursor.execute(query, args)
  File "/home/xiating/.local/lib/python3.5/site-packages/MySQLdb/cursors.py", line 250, in execute
    self.errorhandler(self, exc, value)
  File "/home/xiating/.local/lib/python3.5/site-packages/MySQLdb/connections.py", line 50, in defaulterrorhandler
    raise errorvalue
  File "/home/xiating/.local/lib/python3.5/site-packages/MySQLdb/cursors.py", line 247, in execute
    res = self._query(query)
  File "/home/xiating/.local/lib/python3.5/site-packages/MySQLdb/cursors.py", line 411, in _query
    rowcount = self._do_query(q)
  File "/home/xiating/.local/lib/python3.5/site-packages/MySQLdb/cursors.py", line 374, in _do_query
    db.query(q)
  File "/home/xiating/.local/lib/python3.5/site-packages/MySQLdb/connections.py", line 277, in query
    _mysql.connection.query(self, query)
django.db.utils.DataError: (1406, "Data too long for column 'code' at row 1")
2017-11-28 16:10:22,191:INFO:request course list for dashboard
2017-11-28 16:10:26,028:WARNING:Not Found: /dashboard/lai shi shi kan
2017-11-28 16:13:03,584:INFO:request course list for dashboard
2017-11-28 16:13:35,518:INFO:request course list for dashboard
2017-11-28 16:21:44,497:INFO:request course list for dashboard
2017-11-28 16:22:25,577:WARNING:Not Found: /dashboard/lai shi shi kan
2017-11-28 16:52:26,455:INFO:request course list for dashboard
2017-11-28 16:52:27,154:WARNING:Not Found: /favicon.ico
2017-11-28 16:52:31,064:WARNING:Not Found: /dashboard/lai shi shi kan
2017-11-28 16:54:12,832:INFO:request course list for dashboard
2017-11-28 16:54:14,172:WARNING:Not Found: /dashboard/lai shi shi kan
2017-11-28 16:54:53,182:INFO:request course list for dashboard
2017-11-28 16:54:58,240:WARNING:Not Found: /dashboard/lai shi shi kan
2017-11-28 16:55:21,340:INFO:request course list for dashboard
2017-11-28 16:55:23,967:WARNING:Not Found: /dashboard/lai shi shi kan
2017-11-28 16:56:56,575:INFO:request course list for dashboard
2017-11-28 16:56:58,859:WARNING:request course detail failed: course code = COMP1111
2017-11-28 16:56:59,255:INFO:request course list for dashboard
2017-11-28 16:57:02,693:WARNING:request course detail failed: course code = COMP1111
2017-11-28 16:57:03,075:INFO:request course list for dashboard
2017-11-28 16:57:03,794:WARNING:request course detail failed: course code = COMP1111
2017-11-28 16:57:04,188:INFO:request course list for dashboard
2017-11-28 16:57:09,065:WARNING:request course detail failed: course code = COMP1111
2017-11-28 16:57:09,450:INFO:request course list for dashboard
2017-11-28 17:02:04,393:ERROR:Internal Server Error: /admin/course/course/add/
Traceback (most recent call last):
  File "/home/xiating/.local/lib/python3.5/site-packages/django/core/handlers/exception.py", line 41, in inner
    response = get_response(request)
  File "/home/xiating/.local/lib/python3.5/site-packages/django/core/handlers/base.py", line 187, in _get_response
    response = self.process_exception_by_middleware(e, request)
  File "/home/xiating/.local/lib/python3.5/site-packages/django/core/handlers/base.py", line 185, in _get_response
    response = wrapped_callback(request, *callback_args, **callback_kwargs)
  File "/home/xiating/.local/lib/python3.5/site-packages/django/contrib/admin/options.py", line 551, in wrapper
    return self.admin_site.admin_view(view)(*args, **kwargs)
  File "/home/xiating/.local/lib/python3.5/site-packages/django/utils/decorators.py", line 149, in _wrapped_view
    response = view_func(request, *args, **kwargs)
  File "/home/xiating/.local/lib/python3.5/site-packages/django/views/decorators/cache.py", line 57, in _wrapped_view_func
    response = view_func(request, *args, **kwargs)
  File "/home/xiating/.local/lib/python3.5/site-packages/django/contrib/admin/sites.py", line 224, in inner
    return view(request, *args, **kwargs)
  File "/home/xiating/.local/lib/python3.5/site-packages/django/contrib/admin/options.py", line 1508, in add_view
    return self.changeform_view(request, None, form_url, extra_context)
  File "/home/xiating/.local/lib/python3.5/site-packages/django/utils/decorators.py", line 67, in _wrapper
    return bound_func(*args, **kwargs)
  File "/home/xiating/.local/lib/python3.5/site-packages/django/utils/decorators.py", line 149, in _wrapped_view
    response = view_func(request, *args, **kwargs)
  File "/home/xiating/.local/lib/python3.5/site-packages/django/utils/decorators.py", line 63, in bound_func
    return func.__get__(self, type(self))(*args2, **kwargs2)
  File "/home/xiating/.local/lib/python3.5/site-packages/django/contrib/admin/options.py", line 1408, in changeform_view
    return self._changeform_view(request, object_id, form_url, extra_context)
  File "/home/xiating/.local/lib/python3.5/site-packages/django/contrib/admin/options.py", line 1448, in _changeform_view
    self.save_model(request, new_object, form, not add)
  File "/home/xiating/dbsec/comp3335_project/comp3335/course/admin.py", line 18, in save_model
    if len(obj.code > 100) or len(obj.name > 100):
TypeError: unorderable types: str() > int()
2017-11-28 17:32:33,830:INFO:request course list for dashboard
2017-11-28 17:32:37,639:WARNING:request course detail failed: course code = COMP1111
2017-11-28 17:32:38,020:INFO:request course list for dashboard
2017-11-28 17:32:41,996:WARNING:request course detail failed: course code = COMP1111
2017-11-28 17:32:42,360:INFO:request course list for dashboard
2017-11-28 18:28:03,362:INFO:request course list for dashboard
2017-11-28 18:28:07,138:WARNING:request course detail failed: course code = COMP1111
2017-11-28 18:28:07,523:INFO:request course list for dashboard
>>>>>>> 2a67c4e6bad57a61d2530edd61b602437dcad8ab
2017-11-28 19:31:32,879:ERROR:Internal Server Error: /dashboard/getmessage/
Traceback (most recent call last):
  File "/home/ivan/.local/lib/python3.6/site-packages/django/core/handlers/exception.py", line 41, in inner
    response = get_response(request)
  File "/home/ivan/.local/lib/python3.6/site-packages/django/core/handlers/base.py", line 187, in _get_response
    response = self.process_exception_by_middleware(e, request)
  File "/home/ivan/.local/lib/python3.6/site-packages/django/core/handlers/base.py", line 185, in _get_response
    response = wrapped_callback(request, *callback_args, **callback_kwargs)
  File "/home/ivan/dbs-proj/comp3335/dashboard/views.py", line 75, in getmessage
    logging.info("insert message: course code = " + course_code + ", message = " + message)
NameError: name 'course_code' is not defined
2017-11-28 19:32:04,177:INFO:insert message: course code = , message = asdsad
2017-11-28 19:32:55,811:INFO:insert message: course code = , message = asd
2017-11-28 19:33:18,296:INFO:insert message: course code = , message = asd
2017-11-28 19:34:14,864:INFO:insert message: course code = , message = asd
2017-11-28 19:34:15,213:INFO:insert message: course code = , message = 
2017-11-28 19:34:15,364:INFO:insert message: course code = , message = 
2017-11-28 19:37:04,603:INFO:insert message: course code = , message = asd
2017-11-28 19:37:07,835:INFO:request course detail success: course code = COMP1111
2017-11-28 19:37:08,768:INFO:insert message: course code = , message = 
2017-11-28 19:37:11,268:INFO:insert message: course code = , message = asd
2017-11-28 19:38:04,403:INFO:insert message: course code = , message = asd
2017-11-28 19:38:44,071:INFO:insert message: course code = , message = asd
2017-11-28 19:38:51,706:INFO:request course detail success: course code = COMP1111
2017-11-28 19:38:54,067:INFO:insert message: course code = , message = asd
2017-11-28 19:43:09,011:ERROR:Internal Server Error: /dashboard/getmessage/
Traceback (most recent call last):
  File "/home/ivan/.local/lib/python3.6/site-packages/django/core/handlers/exception.py", line 41, in inner
    response = get_response(request)
  File "/home/ivan/.local/lib/python3.6/site-packages/django/core/handlers/base.py", line 187, in _get_response
    response = self.process_exception_by_middleware(e, request)
  File "/home/ivan/.local/lib/python3.6/site-packages/django/core/handlers/base.py", line 185, in _get_response
    response = wrapped_callback(request, *callback_args, **callback_kwargs)
  File "/home/ivan/dbs-proj/comp3335/dashboard/views.py", line 59, in getmessage
    print(course_id)
NameError: name 'course_id' is not defined
2017-11-28 19:43:33,624:INFO:insert message: course code = COMP1111, message = asd
2017-11-28 19:43:58,453:INFO:insert message: course code = COMP1111, message = asd
2017-11-28 19:44:27,986:INFO:request course detail success: course code = COMP1111
2017-11-28 19:44:29,908:INFO:insert message: course code = COMP1111, message = asd
2017-11-28 19:44:29,908:ERROR:Internal Server Error: /dashboard/getmessage/
Traceback (most recent call last):
  File "/home/ivan/.local/lib/python3.6/site-packages/django/core/handlers/exception.py", line 41, in inner
    response = get_response(request)
  File "/home/ivan/.local/lib/python3.6/site-packages/django/core/handlers/base.py", line 187, in _get_response
    response = self.process_exception_by_middleware(e, request)
  File "/home/ivan/.local/lib/python3.6/site-packages/django/core/handlers/base.py", line 185, in _get_response
    response = wrapped_callback(request, *callback_args, **callback_kwargs)
  File "/home/ivan/dbs-proj/comp3335/dashboard/views.py", line 73, in getmessage
    return JsonResponse(messages, safe=False)
NameError: name 'messages' is not defined
2017-11-28 19:45:02,128:INFO:insert message: course code = COMP1111, message = asd
2017-11-28 19:45:40,324:INFO:request course detail success: course code = COMP1111
2017-11-28 19:45:42,200:ERROR:Internal Server Error: /dashboard/getmessage/
Traceback (most recent call last):
  File "/home/ivan/.local/lib/python3.6/site-packages/django/core/handlers/exception.py", line 41, in inner
    response = get_response(request)
  File "/home/ivan/.local/lib/python3.6/site-packages/django/core/handlers/base.py", line 187, in _get_response
    response = self.process_exception_by_middleware(e, request)
  File "/home/ivan/.local/lib/python3.6/site-packages/django/core/handlers/base.py", line 185, in _get_response
    response = wrapped_callback(request, *callback_args, **callback_kwargs)
  File "/home/ivan/dbs-proj/comp3335/dashboard/views.py", line 73, in getmessage
    logging.info("insert message: course code = " + course_code + ", message = " + m)
TypeError: must be str, not list
2017-11-28 19:45:46,908:ERROR:Internal Server Error: /dashboard/getmessage/
Traceback (most recent call last):
  File "/home/ivan/.local/lib/python3.6/site-packages/django/core/handlers/exception.py", line 41, in inner
    response = get_response(request)
  File "/home/ivan/.local/lib/python3.6/site-packages/django/core/handlers/base.py", line 187, in _get_response
    response = self.process_exception_by_middleware(e, request)
  File "/home/ivan/.local/lib/python3.6/site-packages/django/core/handlers/base.py", line 185, in _get_response
    response = wrapped_callback(request, *callback_args, **callback_kwargs)
  File "/home/ivan/dbs-proj/comp3335/dashboard/views.py", line 73, in getmessage
    logging.info("insert message: course code = " + course_code + ", message = " + m)
TypeError: must be str, not list
2017-11-28 19:46:19,752:INFO:insert message: course code = COMP1111, message = asd
2017-11-28 19:46:41,617:INFO:insert message: course code = COMP1111, message = asd
2017-11-28 19:58:41,963:INFO:insert message: course code = COMP1111, message = asd
2017-11-28 19:59:01,704:INFO:request course detail success: course code = COMP1111
2017-11-28 19:59:05,146:INFO:insert message: course code = COMP1111, message = asd
2017-11-28 19:59:07,491:INFO:insert message: course code = COMP1111, message = ads
2017-11-28 19:59:10,510:INFO:insert message: course code = COMP1111, message = asdsasd
2017-11-28 19:59:48,183:INFO:insert message: course code = COMP1111, message = asd
2017-11-28 19:59:54,594:ERROR:Internal Server Error: /dashboard/getmessage/
Traceback (most recent call last):
  File "/home/ivan/.local/lib/python3.6/site-packages/django/core/handlers/exception.py", line 41, in inner
    response = get_response(request)
  File "/home/ivan/.local/lib/python3.6/site-packages/django/core/handlers/base.py", line 187, in _get_response
    response = self.process_exception_by_middleware(e, request)
  File "/home/ivan/.local/lib/python3.6/site-packages/django/core/handlers/base.py", line 185, in _get_response
    response = wrapped_callback(request, *callback_args, **callback_kwargs)
  File "/home/ivan/dbs-proj/comp3335/dashboard/views.py", line 65, in getmessage
    return render(request, 'dashboard/course_code', {"err": "Sorry... Some fields are too long."})
  File "/home/ivan/.local/lib/python3.6/site-packages/django/shortcuts.py", line 30, in render
    content = loader.render_to_string(template_name, context, request, using=using)
  File "/home/ivan/.local/lib/python3.6/site-packages/django/template/loader.py", line 67, in render_to_string
    template = get_template(template_name, using=using)
  File "/home/ivan/.local/lib/python3.6/site-packages/django/template/loader.py", line 25, in get_template
    raise TemplateDoesNotExist(template_name, chain=chain)
django.template.exceptions.TemplateDoesNotExist: dashboard/course_code
2017-11-28 20:02:52,436:ERROR:Internal Server Error: /dashboard/getmessage/
Traceback (most recent call last):
  File "/home/ivan/.local/lib/python3.6/site-packages/django/core/handlers/exception.py", line 41, in inner
    response = get_response(request)
  File "/home/ivan/.local/lib/python3.6/site-packages/django/core/handlers/base.py", line 198, in _get_response
    "returned None instead." % (callback.__module__, view_name)
ValueError: The view comp3335.dashboard.views.getmessage didn't return an HttpResponse object. It returned None instead.
2017-11-28 20:03:41,205:ERROR:Internal Server Error: /dashboard/getmessage/
Traceback (most recent call last):
  File "/home/ivan/.local/lib/python3.6/site-packages/django/core/handlers/exception.py", line 41, in inner
    response = get_response(request)
  File "/home/ivan/.local/lib/python3.6/site-packages/django/core/handlers/base.py", line 198, in _get_response
    "returned None instead." % (callback.__module__, view_name)
ValueError: The view comp3335.dashboard.views.getmessage didn't return an HttpResponse object. It returned None instead.
2017-11-28 20:05:00,681:WARNING:Not Found: /dashboard/getmessage/too many
2017-11-28 20:13:55,951:INFO:request course detail success: course code = COMP1111
2017-11-28 20:13:57,759:ERROR:Internal Server Error: /dashboard/getmessage/
Traceback (most recent call last):
  File "/home/ivan/.local/lib/python3.6/site-packages/django/core/handlers/exception.py", line 41, in inner
    response = get_response(request)
  File "/home/ivan/.local/lib/python3.6/site-packages/django/core/handlers/base.py", line 187, in _get_response
    response = self.process_exception_by_middleware(e, request)
  File "/home/ivan/.local/lib/python3.6/site-packages/django/core/handlers/base.py", line 185, in _get_response
    response = wrapped_callback(request, *callback_args, **callback_kwargs)
  File "/home/ivan/dbs-proj/comp3335/dashboard/views.py", line 79, in getmessage
    msg = Message(text=msg_encrypt(message),user_id=msg_encrypt(1),course_id=msg_encrypt(course_code))
  File "/home/ivan/dbs-proj/comp3335/utils/encryption.py", line 23, in msg_encrypt
    raw = _pad(raw)
  File "/home/ivan/dbs-proj/comp3335/utils/encryption.py", line 16, in _pad
    return s + (bs - len(s) % bs) * chr(bs - len(s) % bs)
TypeError: object of type 'int' has no len()
2017-11-28 20:24:47,557:ERROR:Internal Server Error: /dashboard/getmessage/
Traceback (most recent call last):
  File "/home/ivan/.local/lib/python3.6/site-packages/django/core/handlers/exception.py", line 41, in inner
    response = get_response(request)
  File "/home/ivan/.local/lib/python3.6/site-packages/django/core/handlers/base.py", line 187, in _get_response
    response = self.process_exception_by_middleware(e, request)
  File "/home/ivan/.local/lib/python3.6/site-packages/django/core/handlers/base.py", line 185, in _get_response
    response = wrapped_callback(request, *callback_args, **callback_kwargs)
  File "/home/ivan/dbs-proj/comp3335/dashboard/views.py", line 80, in getmessage
    msg.save()
  File "/home/ivan/.local/lib/python3.6/site-packages/django/db/models/base.py", line 808, in save
    force_update=force_update, update_fields=update_fields)
  File "/home/ivan/.local/lib/python3.6/site-packages/django/db/models/base.py", line 838, in save_base
    updated = self._save_table(raw, cls, force_insert, force_update, using, update_fields)
  File "/home/ivan/.local/lib/python3.6/site-packages/django/db/models/base.py", line 924, in _save_table
    result = self._do_insert(cls._base_manager, using, fields, update_pk, raw)
  File "/home/ivan/.local/lib/python3.6/site-packages/django/db/models/base.py", line 963, in _do_insert
    using=using, raw=raw)
  File "/home/ivan/.local/lib/python3.6/site-packages/django/db/models/manager.py", line 85, in manager_method
    return getattr(self.get_queryset(), name)(*args, **kwargs)
  File "/home/ivan/.local/lib/python3.6/site-packages/django/db/models/query.py", line 1076, in _insert
    return query.get_compiler(using=using).execute_sql(return_id)
  File "/home/ivan/.local/lib/python3.6/site-packages/django/db/models/sql/compiler.py", line 1106, in execute_sql
    for sql, params in self.as_sql():
  File "/home/ivan/.local/lib/python3.6/site-packages/django/db/models/sql/compiler.py", line 1059, in as_sql
    for obj in self.query.objs
  File "/home/ivan/.local/lib/python3.6/site-packages/django/db/models/sql/compiler.py", line 1059, in <listcomp>
    for obj in self.query.objs
  File "/home/ivan/.local/lib/python3.6/site-packages/django/db/models/sql/compiler.py", line 1058, in <listcomp>
    [self.prepare_value(field, self.pre_save_val(field, obj)) for field in fields]
  File "/home/ivan/.local/lib/python3.6/site-packages/django/db/models/sql/compiler.py", line 998, in prepare_value
    value = field.get_db_prep_save(value, connection=self.connection)
  File "/home/ivan/.local/lib/python3.6/site-packages/django/db/models/fields/related.py", line 963, in get_db_prep_save
    return self.target_field.get_db_prep_save(value, connection=connection)
  File "/home/ivan/.local/lib/python3.6/site-packages/django/db/models/fields/__init__.py", line 770, in get_db_prep_save
    prepared=False)
  File "/home/ivan/.local/lib/python3.6/site-packages/django/db/models/fields/__init__.py", line 958, in get_db_prep_value
    value = self.get_prep_value(value)
  File "/home/ivan/.local/lib/python3.6/site-packages/django/db/models/fields/__init__.py", line 966, in get_prep_value
    return int(value)
ValueError: invalid literal for int() with base 10: '7hdn8rjPiUkQfx5zIwpVVW5posVuyQlj1vbZl1Utgrg='
2017-11-28 20:31:05,560:ERROR:Internal Server Error: /dashboard/getmessage/
Traceback (most recent call last):
  File "/home/ivan/.local/lib/python3.6/site-packages/django/core/handlers/exception.py", line 41, in inner
    response = get_response(request)
  File "/home/ivan/.local/lib/python3.6/site-packages/django/core/handlers/base.py", line 187, in _get_response
    response = self.process_exception_by_middleware(e, request)
  File "/home/ivan/.local/lib/python3.6/site-packages/django/core/handlers/base.py", line 185, in _get_response
    response = wrapped_callback(request, *callback_args, **callback_kwargs)
  File "/home/ivan/dbs-proj/comp3335/dashboard/views.py", line 79, in getmessage
    msg = Message(text=msg_encrypt(message),user=msg_encrypt("1"),course=msg_encrypt(course_code))
  File "/home/ivan/.local/lib/python3.6/site-packages/django/db/models/base.py", line 555, in __init__
    _setattr(self, field.name, rel_obj)
  File "/home/ivan/.local/lib/python3.6/site-packages/django/db/models/fields/related_descriptors.py", line 216, in __set__
    self.field.remote_field.model._meta.object_name,
ValueError: Cannot assign "'rs8MuT1W2SQEQ/bNCpRDk3IsezzpnLOSgxW/moYBo9E='": "Message.user" must be a "Account" instance.
2017-11-28 20:32:37,222:ERROR:Internal Server Error: /dashboard/getmessage/
Traceback (most recent call last):
  File "/home/ivan/.local/lib/python3.6/site-packages/django/core/handlers/exception.py", line 41, in inner
    response = get_response(request)
  File "/home/ivan/.local/lib/python3.6/site-packages/django/core/handlers/base.py", line 187, in _get_response
    response = self.process_exception_by_middleware(e, request)
  File "/home/ivan/.local/lib/python3.6/site-packages/django/core/handlers/base.py", line 185, in _get_response
    response = wrapped_callback(request, *callback_args, **callback_kwargs)
  File "/home/ivan/dbs-proj/comp3335/dashboard/views.py", line 79, in getmessage
    msg = Message.objects.create(text=msg_encrypt(message),user=msg_encrypt("1"),course=msg_encrypt(course_code))
  File "/home/ivan/.local/lib/python3.6/site-packages/django/db/models/manager.py", line 85, in manager_method
    return getattr(self.get_queryset(), name)(*args, **kwargs)
  File "/home/ivan/.local/lib/python3.6/site-packages/django/db/models/query.py", line 392, in create
    obj = self.model(**kwargs)
  File "/home/ivan/.local/lib/python3.6/site-packages/django/db/models/base.py", line 555, in __init__
    _setattr(self, field.name, rel_obj)
  File "/home/ivan/.local/lib/python3.6/site-packages/django/db/models/fields/related_descriptors.py", line 216, in __set__
    self.field.remote_field.model._meta.object_name,
ValueError: Cannot assign "'aJAaP/7XxiBVQStsZ9vH5VKQvnTQFYxs+8kE0XCjyWM='": "Message.user" must be a "Account" instance.
2017-11-28 20:33:08,790:ERROR:Internal Server Error: /dashboard/getmessage/
Traceback (most recent call last):
  File "/home/ivan/.local/lib/python3.6/site-packages/django/core/handlers/exception.py", line 41, in inner
    response = get_response(request)
  File "/home/ivan/.local/lib/python3.6/site-packages/django/core/handlers/base.py", line 187, in _get_response
    response = self.process_exception_by_middleware(e, request)
  File "/home/ivan/.local/lib/python3.6/site-packages/django/core/handlers/base.py", line 185, in _get_response
    response = wrapped_callback(request, *callback_args, **callback_kwargs)
  File "/home/ivan/dbs-proj/comp3335/dashboard/views.py", line 79, in getmessage
    msg = Message.objects.create(text=msg_encrypt(message),user="1",course=course_code)
  File "/home/ivan/.local/lib/python3.6/site-packages/django/db/models/manager.py", line 85, in manager_method
    return getattr(self.get_queryset(), name)(*args, **kwargs)
  File "/home/ivan/.local/lib/python3.6/site-packages/django/db/models/query.py", line 392, in create
    obj = self.model(**kwargs)
  File "/home/ivan/.local/lib/python3.6/site-packages/django/db/models/base.py", line 555, in __init__
    _setattr(self, field.name, rel_obj)
  File "/home/ivan/.local/lib/python3.6/site-packages/django/db/models/fields/related_descriptors.py", line 216, in __set__
    self.field.remote_field.model._meta.object_name,
ValueError: Cannot assign "'1'": "Message.user" must be a "Account" instance.
2017-11-28 20:34:01,973:ERROR:Internal Server Error: /dashboard/getmessage/
Traceback (most recent call last):
  File "/home/ivan/.local/lib/python3.6/site-packages/django/core/handlers/exception.py", line 41, in inner
    response = get_response(request)
  File "/home/ivan/.local/lib/python3.6/site-packages/django/core/handlers/base.py", line 187, in _get_response
    response = self.process_exception_by_middleware(e, request)
  File "/home/ivan/.local/lib/python3.6/site-packages/django/core/handlers/base.py", line 185, in _get_response
    response = wrapped_callback(request, *callback_args, **callback_kwargs)
  File "/home/ivan/dbs-proj/comp3335/dashboard/views.py", line 79, in getmessage
    msg = Message.objects.create(text=msg_encrypt(message),user=1,course=course_code)
  File "/home/ivan/.local/lib/python3.6/site-packages/django/db/models/manager.py", line 85, in manager_method
    return getattr(self.get_queryset(), name)(*args, **kwargs)
  File "/home/ivan/.local/lib/python3.6/site-packages/django/db/models/query.py", line 392, in create
    obj = self.model(**kwargs)
  File "/home/ivan/.local/lib/python3.6/site-packages/django/db/models/base.py", line 555, in __init__
    _setattr(self, field.name, rel_obj)
  File "/home/ivan/.local/lib/python3.6/site-packages/django/db/models/fields/related_descriptors.py", line 216, in __set__
    self.field.remote_field.model._meta.object_name,
ValueError: Cannot assign "1": "Message.user" must be a "Account" instance.
2017-11-28 20:36:01,087:ERROR:Internal Server Error: /dashboard/getmessage/
Traceback (most recent call last):
  File "/home/ivan/.local/lib/python3.6/site-packages/django/core/handlers/exception.py", line 41, in inner
    response = get_response(request)
  File "/home/ivan/.local/lib/python3.6/site-packages/django/core/handlers/base.py", line 187, in _get_response
    response = self.process_exception_by_middleware(e, request)
  File "/home/ivan/.local/lib/python3.6/site-packages/django/core/handlers/base.py", line 185, in _get_response
    response = wrapped_callback(request, *callback_args, **callback_kwargs)
  File "/home/ivan/dbs-proj/comp3335/dashboard/views.py", line 78, in getmessage
    user = Account(id=1)
NameError: name 'Account' is not defined
2017-11-28 20:37:01,493:ERROR:Internal Server Error: /dashboard/getmessage/
Traceback (most recent call last):
  File "/home/ivan/.local/lib/python3.6/site-packages/django/core/handlers/exception.py", line 41, in inner
    response = get_response(request)
  File "/home/ivan/.local/lib/python3.6/site-packages/django/core/handlers/base.py", line 187, in _get_response
    response = self.process_exception_by_middleware(e, request)
  File "/home/ivan/.local/lib/python3.6/site-packages/django/core/handlers/base.py", line 185, in _get_response
    response = wrapped_callback(request, *callback_args, **callback_kwargs)
  File "/home/ivan/dbs-proj/comp3335/dashboard/views.py", line 78, in getmessage
    user = Account.objects.first()
NameError: name 'Account' is not defined
2017-11-28 20:37:27,625:ERROR:Internal Server Error: /dashboard/getmessage/
Traceback (most recent call last):
  File "/home/ivan/.local/lib/python3.6/site-packages/django/core/handlers/exception.py", line 41, in inner
    response = get_response(request)
  File "/home/ivan/.local/lib/python3.6/site-packages/django/core/handlers/base.py", line 187, in _get_response
    response = self.process_exception_by_middleware(e, request)
  File "/home/ivan/.local/lib/python3.6/site-packages/django/core/handlers/base.py", line 185, in _get_response
    response = wrapped_callback(request, *callback_args, **callback_kwargs)
  File "/home/ivan/dbs-proj/comp3335/dashboard/views.py", line 80, in getmessage
    msg = Message.objects.create(text=msg_encrypt(message),user=user,course=course_code)
  File "/home/ivan/.local/lib/python3.6/site-packages/django/db/models/manager.py", line 85, in manager_method
    return getattr(self.get_queryset(), name)(*args, **kwargs)
  File "/home/ivan/.local/lib/python3.6/site-packages/django/db/models/query.py", line 392, in create
    obj = self.model(**kwargs)
  File "/home/ivan/.local/lib/python3.6/site-packages/django/db/models/base.py", line 555, in __init__
    _setattr(self, field.name, rel_obj)
  File "/home/ivan/.local/lib/python3.6/site-packages/django/db/models/fields/related_descriptors.py", line 216, in __set__
    self.field.remote_field.model._meta.object_name,
ValueError: Cannot assign "'COMP1111'": "Message.course" must be a "Course" instance.
2017-11-28 20:40:09,795:ERROR:Internal Server Error: /dashboard/getmessage/
Traceback (most recent call last):
  File "/home/ivan/.local/lib/python3.6/site-packages/django/core/handlers/exception.py", line 41, in inner
    response = get_response(request)
  File "/home/ivan/.local/lib/python3.6/site-packages/django/core/handlers/base.py", line 187, in _get_response
    response = self.process_exception_by_middleware(e, request)
  File "/home/ivan/.local/lib/python3.6/site-packages/django/core/handlers/base.py", line 185, in _get_response
    response = wrapped_callback(request, *callback_args, **callback_kwargs)
  File "/home/ivan/dbs-proj/comp3335/dashboard/views.py", line 80, in getmessage
    course = Course.objects.get(code = course_code)
  File "/home/ivan/.local/lib/python3.6/site-packages/django/db/models/manager.py", line 85, in manager_method
    return getattr(self.get_queryset(), name)(*args, **kwargs)
  File "/home/ivan/.local/lib/python3.6/site-packages/django/db/models/query.py", line 380, in get
    self.model._meta.object_name
comp3335.course.models.DoesNotExist: Course matching query does not exist.
2017-11-28 20:43:00,671:ERROR:Internal Server Error: /dashboard/getmessage/
Traceback (most recent call last):
  File "/home/ivan/.local/lib/python3.6/site-packages/django/core/handlers/exception.py", line 41, in inner
    response = get_response(request)
  File "/home/ivan/.local/lib/python3.6/site-packages/django/core/handlers/base.py", line 187, in _get_response
    response = self.process_exception_by_middleware(e, request)
  File "/home/ivan/.local/lib/python3.6/site-packages/django/core/handlers/base.py", line 185, in _get_response
    response = wrapped_callback(request, *callback_args, **callback_kwargs)
  File "/home/ivan/dbs-proj/comp3335/dashboard/views.py", line 85, in getmessage
    course = Course.objects.get(code = c.code)
  File "/home/ivan/.local/lib/python3.6/site-packages/django/db/models/manager.py", line 85, in manager_method
    return getattr(self.get_queryset(), name)(*args, **kwargs)
  File "/home/ivan/.local/lib/python3.6/site-packages/django/db/models/query.py", line 380, in get
    self.model._meta.object_name
comp3335.course.models.DoesNotExist: Course matching query does not exist.
2017-11-28 20:43:43,276:ERROR:Internal Server Error: /dashboard/getmessage/
Traceback (most recent call last):
  File "/home/ivan/.local/lib/python3.6/site-packages/django/core/handlers/exception.py", line 41, in inner
    response = get_response(request)
  File "/home/ivan/.local/lib/python3.6/site-packages/django/core/handlers/base.py", line 187, in _get_response
    response = self.process_exception_by_middleware(e, request)
  File "/home/ivan/.local/lib/python3.6/site-packages/django/core/handlers/base.py", line 185, in _get_response
    response = wrapped_callback(request, *callback_args, **callback_kwargs)
  File "/home/ivan/dbs-proj/comp3335/dashboard/views.py", line 86, in getmessage
    course = Course.objects.get(code = c.code)
  File "/home/ivan/.local/lib/python3.6/site-packages/django/db/models/manager.py", line 85, in manager_method
    return getattr(self.get_queryset(), name)(*args, **kwargs)
  File "/home/ivan/.local/lib/python3.6/site-packages/django/db/models/query.py", line 380, in get
    self.model._meta.object_name
comp3335.course.models.DoesNotExist: Course matching query does not exist.
2017-11-28 20:44:19,142:ERROR:Internal Server Error: /dashboard/getmessage/
Traceback (most recent call last):
  File "/home/ivan/.local/lib/python3.6/site-packages/django/core/handlers/exception.py", line 41, in inner
    response = get_response(request)
  File "/home/ivan/.local/lib/python3.6/site-packages/django/core/handlers/base.py", line 187, in _get_response
    response = self.process_exception_by_middleware(e, request)
  File "/home/ivan/.local/lib/python3.6/site-packages/django/core/handlers/base.py", line 185, in _get_response
    response = wrapped_callback(request, *callback_args, **callback_kwargs)
  File "/home/ivan/dbs-proj/comp3335/dashboard/views.py", line 86, in getmessage
    course = Course.objects.get(code = c.code)
  File "/home/ivan/.local/lib/python3.6/site-packages/django/db/models/manager.py", line 85, in manager_method
    return getattr(self.get_queryset(), name)(*args, **kwargs)
  File "/home/ivan/.local/lib/python3.6/site-packages/django/db/models/query.py", line 380, in get
    self.model._meta.object_name
comp3335.course.models.DoesNotExist: Course matching query does not exist.
2017-11-28 20:45:10,006:ERROR:Internal Server Error: /dashboard/getmessage/
Traceback (most recent call last):
  File "/home/ivan/.local/lib/python3.6/site-packages/django/core/handlers/exception.py", line 41, in inner
    response = get_response(request)
  File "/home/ivan/.local/lib/python3.6/site-packages/django/core/handlers/base.py", line 187, in _get_response
    response = self.process_exception_by_middleware(e, request)
  File "/home/ivan/.local/lib/python3.6/site-packages/django/core/handlers/base.py", line 185, in _get_response
    response = wrapped_callback(request, *callback_args, **callback_kwargs)
  File "/home/ivan/dbs-proj/comp3335/dashboard/views.py", line 87, in getmessage
    course = Course.objects.get(code = c.code)
  File "/home/ivan/.local/lib/python3.6/site-packages/django/db/models/manager.py", line 85, in manager_method
    return getattr(self.get_queryset(), name)(*args, **kwargs)
  File "/home/ivan/.local/lib/python3.6/site-packages/django/db/models/query.py", line 380, in get
    self.model._meta.object_name
comp3335.course.models.DoesNotExist: Course matching query does not exist.
2017-11-28 20:45:42,331:ERROR:Internal Server Error: /dashboard/getmessage/
Traceback (most recent call last):
  File "/home/ivan/.local/lib/python3.6/site-packages/django/core/handlers/exception.py", line 41, in inner
    response = get_response(request)
  File "/home/ivan/.local/lib/python3.6/site-packages/django/core/handlers/base.py", line 187, in _get_response
    response = self.process_exception_by_middleware(e, request)
  File "/home/ivan/.local/lib/python3.6/site-packages/django/core/handlers/base.py", line 185, in _get_response
    response = wrapped_callback(request, *callback_args, **callback_kwargs)
  File "/home/ivan/dbs-proj/comp3335/dashboard/views.py", line 88, in getmessage
    course = Course.objects.get(code = c.code)
  File "/home/ivan/.local/lib/python3.6/site-packages/django/db/models/manager.py", line 85, in manager_method
    return getattr(self.get_queryset(), name)(*args, **kwargs)
  File "/home/ivan/.local/lib/python3.6/site-packages/django/db/models/query.py", line 380, in get
    self.model._meta.object_name
comp3335.course.models.DoesNotExist: Course matching query does not exist.
2017-11-28 20:46:33,586:INFO:insert message: course code = COMP1111, message = asd
2017-11-28 20:48:46,884:INFO:insert message: course code = COMP1111, message = asdsds
2017-11-28 20:51:31,593:INFO:insert message: course code = COMP1111, message = sadsd
2017-11-28 20:53:25,526:INFO:request course list for dashboard
2017-11-28 20:53:28,278:ERROR:Internal Server Error: /dashboard/COMP1111/
Traceback (most recent call last):
  File "/home/ivan/.local/lib/python3.6/site-packages/django/core/handlers/exception.py", line 41, in inner
    response = get_response(request)
  File "/home/ivan/.local/lib/python3.6/site-packages/django/core/handlers/base.py", line 187, in _get_response
    response = self.process_exception_by_middleware(e, request)
  File "/home/ivan/.local/lib/python3.6/site-packages/django/core/handlers/base.py", line 185, in _get_response
    response = wrapped_callback(request, *callback_args, **callback_kwargs)
  File "/home/ivan/dbs-proj/comp3335/dashboard/views.py", line 44, in coursedetail
    if course_id in msg.course_id:
TypeError: argument of type 'int' is not iterable
2017-11-28 20:55:17,276:ERROR:Internal Server Error: /dashboard/COMP1111/
Traceback (most recent call last):
  File "/home/ivan/.local/lib/python3.6/site-packages/django/core/handlers/exception.py", line 41, in inner
    response = get_response(request)
  File "/home/ivan/.local/lib/python3.6/site-packages/django/core/handlers/base.py", line 187, in _get_response
    response = self.process_exception_by_middleware(e, request)
  File "/home/ivan/.local/lib/python3.6/site-packages/django/core/handlers/base.py", line 185, in _get_response
    response = wrapped_callback(request, *callback_args, **callback_kwargs)
  File "/home/ivan/dbs-proj/comp3335/dashboard/views.py", line 44, in coursedetail
    if course_id in msg.course_id:
TypeError: argument of type 'int' is not iterable
2017-11-28 20:57:50,512:ERROR:Internal Server Error: /dashboard/COMP1111/
Traceback (most recent call last):
  File "/home/ivan/.local/lib/python3.6/site-packages/django/core/handlers/exception.py", line 41, in inner
    response = get_response(request)
  File "/home/ivan/.local/lib/python3.6/site-packages/django/core/handlers/base.py", line 187, in _get_response
    response = self.process_exception_by_middleware(e, request)
  File "/home/ivan/.local/lib/python3.6/site-packages/django/core/handlers/base.py", line 185, in _get_response
    response = wrapped_callback(request, *callback_args, **callback_kwargs)
  File "/home/ivan/dbs-proj/comp3335/dashboard/views.py", line 38, in coursedetail
    if course_code in course.code:
NameError: name 'course_code' is not defined
2017-11-28 21:00:24,189:ERROR:Internal Server Error: /dashboard/COMP1111/
Traceback (most recent call last):
  File "/home/ivan/.local/lib/python3.6/site-packages/django/core/handlers/exception.py", line 41, in inner
    response = get_response(request)
  File "/home/ivan/.local/lib/python3.6/site-packages/django/core/handlers/base.py", line 187, in _get_response
    response = self.process_exception_by_middleware(e, request)
  File "/home/ivan/.local/lib/python3.6/site-packages/django/core/handlers/base.py", line 185, in _get_response
    response = wrapped_callback(request, *callback_args, **callback_kwargs)
  File "/home/ivan/dbs-proj/comp3335/dashboard/views.py", line 38, in coursedetail
    if course_code in course.code:
NameError: name 'course_code' is not defined
2017-11-28 21:04:09,191:ERROR:Internal Server Error: /dashboard/COMP1111/
Traceback (most recent call last):
  File "/home/ivan/.local/lib/python3.6/site-packages/django/core/handlers/exception.py", line 41, in inner
    response = get_response(request)
  File "/home/ivan/.local/lib/python3.6/site-packages/django/core/handlers/base.py", line 187, in _get_response
    response = self.process_exception_by_middleware(e, request)
  File "/home/ivan/.local/lib/python3.6/site-packages/django/core/handlers/base.py", line 185, in _get_response
    response = wrapped_callback(request, *callback_args, **callback_kwargs)
  File "/home/ivan/dbs-proj/comp3335/dashboard/views.py", line 45, in coursedetail
    if course_id in msg.course_id:
TypeError: argument of type 'int' is not iterable
2017-11-28 21:05:02,194:INFO:request course detail success: course code = COMP1111
2017-11-28 21:05:06,131:INFO:insert message: course code = COMP1111, message = asd
2017-11-28 21:05:09,231:INFO:insert message: course code = COMP1111, message = fafadfa
2017-11-28 21:07:59,668:INFO:request course detail success: course code = COMP1111
2017-11-28 21:09:04,488:INFO:request course detail success: course code = COMP1111
2017-11-28 21:10:22,214:ERROR:Internal Server Error: /dashboard/COMP1111/
Traceback (most recent call last):
  File "/home/ivan/.local/lib/python3.6/site-packages/django/core/handlers/exception.py", line 41, in inner
    response = get_response(request)
  File "/home/ivan/.local/lib/python3.6/site-packages/django/core/handlers/base.py", line 187, in _get_response
    response = self.process_exception_by_middleware(e, request)
  File "/home/ivan/.local/lib/python3.6/site-packages/django/core/handlers/base.py", line 185, in _get_response
    response = wrapped_callback(request, *callback_args, **callback_kwargs)
  File "/home/ivan/dbs-proj/comp3335/dashboard/views.py", line 38, in coursedetail
    if course_id in course.id:
TypeError: argument of type 'int' is not iterable
2017-11-28 21:10:30,406:WARNING:request course detail failed: course code = COMP1111
2017-11-28 21:10:30,765:INFO:request course list for dashboard
2017-11-28 21:10:32,751:WARNING:request course detail failed: course code = COMP1111
2017-11-28 21:10:33,094:INFO:request course list for dashboard
2017-11-28 21:10:44,661:INFO:request course detail success: course code = COMP1111
2017-11-28 21:11:07,275:INFO:request course detail success: course code = COMP1111
2017-11-28 21:12:28,031:INFO:request course detail success: course code = COMP1111
2017-11-28 21:24:28,699:INFO:request course list for dashboard
2017-11-28 21:24:30,370:INFO:request course detail success: course code = COMP1111
2017-11-28 21:24:35,090:INFO:insert message: course code = COMP1111, message = asjdklasjkdlsakjda
2017-11-28 21:24:45,587:INFO:insert message: course code = COMP1111, message = sadasd
2017-11-28 21:25:28,728:INFO:insert message: course code = COMP1111, message = adsfdsfsdf
2017-11-28 21:27:17,833:INFO:insert message: course code = COMP1111, message = asdasd
2017-11-28 21:27:36,756:INFO:request course list for dashboard
2017-11-28 21:27:37,993:INFO:request course detail success: course code = COMP1111
2017-11-28 21:29:25,167:INFO:insert message: course code = COMP1111, message = asds
2017-11-28 21:29:25,174:WARNING:Not Found: /dashboard/getmessage/dashboard/board/coursedetail.html
2017-11-28 21:29:34,344:INFO:insert message: course code = COMP1111, message = asdf
2017-11-28 21:29:34,352:WARNING:Not Found: /dashboard/board/coursedetail.html
2017-11-28 21:29:36,355:INFO:request course detail success: course code = COMP1111
2017-11-28 21:30:06,509:INFO:insert message: course code = COMP1111, message = asdsd
2017-11-28 21:30:06,873:INFO:request course list for dashboard
2017-11-28 21:31:17,032:INFO:insert message: course code = COMP1111, message = dafsda
2017-11-28 21:31:17,038:WARNING:Not Found: /dashboard/getmessage/dashboard/board/coursedetail.html
2017-11-28 21:31:22,252:INFO:request course detail success: course code = COMP1111
2017-11-28 21:35:45,322:INFO:request course detail success: course code = COMP1111
2017-11-28 21:35:48,821:INFO:insert message: course code = COMP1111, message = sadjsajda;sjdalskd
2017-11-28 21:35:48,911:INFO:request course detail success: course code = COMP1111
2017-11-28 21:44:30,272:INFO:request course detail success: course code = COMP1111
2017-11-28 21:44:34,785:INFO:insert message: course code = COMP1111, message = asdfasdfasd
2017-11-28 21:44:45,810:INFO:request course detail success: course code = COMP1111
2017-11-28 21:48:12,401:INFO:insert message: course code = COMP1111, message = asdfdsa
2017-11-28 21:48:23,225:INFO:request course detail success: course code = COMP1111
2017-11-28 21:49:41,573:INFO:request course detail success: course code = COMP1111
2017-11-28 21:49:44,684:INFO:insert message: course code = COMP1111, message = adsfdas
2017-11-28 21:49:44,694:WARNING:Not Found: /dashboard/getmessage/dashboard/board/coursedetail.html
2017-11-28 21:49:54,214:INFO:request course detail success: course code = COMP1111
2017-11-28 21:50:00,732:INFO:insert message: course code = COMP1111, message = sdasd
2017-11-28 21:50:00,738:WARNING:Not Found: /dashboard/getmessage/dashboard/board/coursedetail.html
2017-11-28 21:50:14,520:INFO:request course list for dashboard
2017-11-28 21:50:16,473:INFO:request course detail success: course code = COMP1111
2017-11-28 21:50:21,247:INFO:insert message: course code = COMP1111, message = unnexpected
2017-11-28 21:50:21,258:WARNING:Not Found: /dashboard/board/coursedetail.html
2017-11-28 21:50:24,570:INFO:insert message: course code = COMP1111, message = findings
2017-11-28 21:50:24,580:WARNING:Not Found: /dashboard/board/coursedetail.html
2017-11-28 21:55:08,716:INFO:request course detail success: course code = COMP1111
2017-11-28 21:55:11,908:INFO:insert message: course code = COMP1111, message = asdsa
2017-11-28 21:55:11,908:ERROR:Internal Server Error: /dashboard/getmessage/
Traceback (most recent call last):
  File "/home/ivan/.local/lib/python3.6/site-packages/django/core/handlers/exception.py", line 41, in inner
    response = get_response(request)
  File "/home/ivan/.local/lib/python3.6/site-packages/django/core/handlers/base.py", line 198, in _get_response
    "returned None instead." % (callback.__module__, view_name)
ValueError: The view comp3335.dashboard.views.getmessage didn't return an HttpResponse object. It returned None instead.
2017-11-28 21:56:12,378:INFO:request course detail success: course code = COMP1111
2017-11-28 21:56:18,981:INFO:insert message: course code = COMP1111, message = asdsasddsfa
2017-11-28 21:56:22,298:INFO:request course detail success: course code = COMP1111
2017-11-28 21:56:37,884:INFO:request course detail success: course code = COMP1111
2017-11-28 21:56:42,638:INFO:insert message: course code = COMP1111, message = fsd
2017-11-28 21:56:42,644:WARNING:Not Found: /dashboard/getmessage/dashboard/board/coursedetail.html
2017-11-28 21:56:43,185:INFO:insert message: course code = COMP1111, message = 
2017-11-28 21:56:43,190:WARNING:Not Found: /dashboard/getmessage/dashboard/board/coursedetail.html
2017-11-28 21:56:48,955:INFO:request course detail success: course code = COMP1111
2017-11-28 21:56:52,159:INFO:insert message: course code = COMP1111, message = sad
2017-11-28 21:56:52,165:WARNING:Not Found: /dashboard/board/coursedetail.html
2017-11-28 21:57:46,764:INFO:request course detail success: course code = COMP1111
2017-11-28 21:58:10,761:INFO:insert message: course code = COMP1111, message = asdsaf
2017-11-28 21:58:10,805:INFO:request course detail success: course code = COMP1111
2017-11-28 21:59:09,386:INFO:request course detail success: course code = COMP1111
2017-11-28 21:59:12,869:INFO:insert message: course code = COMP1111, message = agf
2017-11-28 21:59:12,913:INFO:request course detail success: course code = COMP1111
2017-11-28 21:59:12,963:ERROR:Internal Server Error: /dashboard/getmessage/
Traceback (most recent call last):
  File "/home/ivan/.local/lib/python3.6/site-packages/django/core/handlers/exception.py", line 41, in inner
    response = get_response(request)
  File "/home/ivan/.local/lib/python3.6/site-packages/django/core/handlers/base.py", line 198, in _get_response
    "returned None instead." % (callback.__module__, view_name)
ValueError: The view comp3335.dashboard.views.getmessage didn't return an HttpResponse object. It returned None instead.
2017-11-28 22:07:33,992:INFO:request course detail success: course code = COMP1111
2017-11-28 22:07:39,765:INFO:insert message: course code = COMP1111, message = asgfasdgasdg
2017-11-28 22:07:56,857:INFO:request course detail success: course code = COMP1111
2017-11-28 22:08:02,829:INFO:insert message: course code = COMP1111, message = adsfasdfsdasadfsadfasd
2017-11-28 22:08:02,876:ERROR:Internal Server Error: /dashboard/getmessage/
Traceback (most recent call last):
  File "/home/ivan/.local/lib/python3.6/site-packages/django/core/handlers/exception.py", line 41, in inner
    response = get_response(request)
  File "/home/ivan/.local/lib/python3.6/site-packages/django/core/handlers/base.py", line 187, in _get_response
    response = self.process_exception_by_middleware(e, request)
  File "/home/ivan/.local/lib/python3.6/site-packages/django/core/handlers/base.py", line 185, in _get_response
    response = wrapped_callback(request, *callback_args, **callback_kwargs)
  File "/home/ivan/dbs-proj/comp3335/dashboard/views.py", line 87, in getmessage
    m.append(msg_decrypted(ms.text))
NameError: name 'msg_decrypted' is not defined
2017-11-28 22:08:20,258:INFO:request course detail success: course code = COMP1111
2017-11-28 22:08:24,714:INFO:insert message: course code = COMP1111, message = sadfllkjaslkfklasfsklfjasd
2017-11-28 22:09:41,055:INFO:insert message: course code = COMP1111, message = asd
2017-11-28 22:14:30,675:INFO:request course list for dashboard
2017-11-28 22:14:32,753:INFO:request course detail success: course code = COMP1111
2017-11-28 22:14:35,940:INFO:insert message: course code = COMP1111, message = hi
2017-11-28 22:20:48,921:INFO:insert message: course code = COMP1111, message = asdas
2017-11-28 22:21:26,682:INFO:insert message: course code = COMP1111, message = asd
2017-11-28 22:21:39,931:INFO:insert message: course code = COMP1111, message = adsf
2017-11-28 22:21:56,221:INFO:insert message: course code = COMP1111, message = asdf
2017-11-28 22:22:23,484:INFO:insert message: course code = COMP1111, message = sadf
2017-11-28 22:24:38,959:INFO:request course list for dashboard
2017-11-28 22:24:40,758:INFO:request course detail success: course code = COMP1111
2017-11-28 22:24:50,059:INFO:insert message: course code = COMP1111, message = what
2017-11-28 22:28:10,494:INFO:insert message: course code = COMP1111, message = safsa
2017-11-28 22:28:34,262:INFO:insert message: course code = COMP1111, message = asdssadf
2017-11-28 22:29:00,840:INFO:insert message: course code = COMP1111, message = fsadfsad
2017-11-28 22:29:46,003:INFO:insert message: course code = COMP1111, message = asdfasdf
2017-11-28 22:29:57,358:INFO:insert message: course code = COMP1111, message = asd
2017-11-28 22:29:57,902:INFO:insert message: course code = COMP1111, message = fa
2017-11-28 22:30:29,777:INFO:insert message: course code = COMP1111, message = hhh
2017-11-28 22:34:27,433:INFO:insert message: course code = COMP1111, message = asdfsda
2017-11-28 22:34:27,456:ERROR:Internal Server Error: /dashboard/getmessage/
Traceback (most recent call last):
  File "/home/ivan/.local/lib/python3.6/site-packages/django/core/handlers/exception.py", line 41, in inner
    response = get_response(request)
  File "/home/ivan/.local/lib/python3.6/site-packages/django/core/handlers/base.py", line 187, in _get_response
    response = self.process_exception_by_middleware(e, request)
  File "/home/ivan/.local/lib/python3.6/site-packages/django/core/handlers/base.py", line 185, in _get_response
    response = wrapped_callback(request, *callback_args, **callback_kwargs)
  File "/home/ivan/dbs-proj/comp3335/dashboard/views.py", line 88, in getmessage
    for ms in msgResult[:-2]:
  File "/home/ivan/.local/lib/python3.6/site-packages/django/db/models/query.py", line 269, in __getitem__
    "Negative indexing is not supported."
AssertionError: Negative indexing is not supported.
2017-11-28 22:34:30,726:INFO:request course detail success: course code = COMP1111
2017-11-28 22:34:37,000:INFO:insert message: course code = COMP1111, message = asdjfl
2017-11-28 22:34:37,008:ERROR:Internal Server Error: /dashboard/getmessage/
Traceback (most recent call last):
  File "/home/ivan/.local/lib/python3.6/site-packages/django/core/handlers/exception.py", line 41, in inner
    response = get_response(request)
  File "/home/ivan/.local/lib/python3.6/site-packages/django/core/handlers/base.py", line 187, in _get_response
    response = self.process_exception_by_middleware(e, request)
  File "/home/ivan/.local/lib/python3.6/site-packages/django/core/handlers/base.py", line 185, in _get_response
    response = wrapped_callback(request, *callback_args, **callback_kwargs)
  File "/home/ivan/dbs-proj/comp3335/dashboard/views.py", line 88, in getmessage
    for ms in msgResult[:-2]:
  File "/home/ivan/.local/lib/python3.6/site-packages/django/db/models/query.py", line 269, in __getitem__
    "Negative indexing is not supported."
AssertionError: Negative indexing is not supported.
2017-11-28 22:34:43,902:INFO:insert message: course code = COMP1111, message = ads;lka;sdk
2017-11-28 22:34:43,905:ERROR:Internal Server Error: /dashboard/getmessage/
Traceback (most recent call last):
  File "/home/ivan/.local/lib/python3.6/site-packages/django/core/handlers/exception.py", line 41, in inner
    response = get_response(request)
  File "/home/ivan/.local/lib/python3.6/site-packages/django/core/handlers/base.py", line 187, in _get_response
    response = self.process_exception_by_middleware(e, request)
  File "/home/ivan/.local/lib/python3.6/site-packages/django/core/handlers/base.py", line 185, in _get_response
    response = wrapped_callback(request, *callback_args, **callback_kwargs)
  File "/home/ivan/dbs-proj/comp3335/dashboard/views.py", line 88, in getmessage
    for ms in msgResult[:-2]:
  File "/home/ivan/.local/lib/python3.6/site-packages/django/db/models/query.py", line 269, in __getitem__
    "Negative indexing is not supported."
AssertionError: Negative indexing is not supported.
2017-11-28 22:34:47,491:INFO:insert message: course code = COMP1111, message = afsdaf
2017-11-28 22:34:47,571:ERROR:Internal Server Error: /dashboard/getmessage/
Traceback (most recent call last):
  File "/home/ivan/.local/lib/python3.6/site-packages/django/core/handlers/exception.py", line 41, in inner
    response = get_response(request)
  File "/home/ivan/.local/lib/python3.6/site-packages/django/core/handlers/base.py", line 187, in _get_response
    response = self.process_exception_by_middleware(e, request)
  File "/home/ivan/.local/lib/python3.6/site-packages/django/core/handlers/base.py", line 185, in _get_response
    response = wrapped_callback(request, *callback_args, **callback_kwargs)
  File "/home/ivan/dbs-proj/comp3335/dashboard/views.py", line 88, in getmessage
    for ms in msgResult[:-2]:
  File "/home/ivan/.local/lib/python3.6/site-packages/django/db/models/query.py", line 269, in __getitem__
    "Negative indexing is not supported."
AssertionError: Negative indexing is not supported.
2017-11-28 22:35:49,979:INFO:request course list for dashboard
2017-11-28 22:35:55,655:INFO:request course detail success: course code = COMP1111
2017-11-28 22:36:05,927:INFO:insert message: course code = COMP1111, message = asdfasdfasdf
2017-11-29 00:32:34,206:ERROR:Internal Server Error: /search/data
Traceback (most recent call last):
  File "/home/ivan/dbs-proj/comp3335/search/views.py", line 14, in search
    authorized = request.session['authorized']
  File "/home/ivan/.local/lib/python3.6/site-packages/django/contrib/sessions/backends/base.py", line 57, in __getitem__
    return self._session[key]
KeyError: 'authorized'

During handling of the above exception, another exception occurred:

Traceback (most recent call last):
  File "/home/ivan/.local/lib/python3.6/site-packages/django/core/handlers/exception.py", line 41, in inner
    response = get_response(request)
  File "/home/ivan/.local/lib/python3.6/site-packages/django/core/handlers/base.py", line 187, in _get_response
    response = self.process_exception_by_middleware(e, request)
  File "/home/ivan/.local/lib/python3.6/site-packages/django/core/handlers/base.py", line 185, in _get_response
    response = wrapped_callback(request, *callback_args, **callback_kwargs)
  File "/home/ivan/.local/lib/python3.6/site-packages/django/views/decorators/csrf.py", line 58, in wrapped_view
    return view_func(*args, **kwargs)
  File "/home/ivan/dbs-proj/comp3335/search/views.py", line 16, in search
    return redirect('/account/register.html')
NameError: name 'redirect' is not defined
2017-11-29 00:34:40,716:INFO:request course list for dashboard
2017-11-29 00:34:45,215:INFO:request course detail success: course code = COMP1111
2017-11-29 00:34:52,728:WARNING:Not Found: /dashboard/search
2017-11-29 00:41:23,446:ERROR:Internal Server Error: /search/data
Traceback (most recent call last):
  File "/home/ivan/.local/lib/python3.6/site-packages/django/core/handlers/exception.py", line 41, in inner
    response = get_response(request)
  File "/home/ivan/.local/lib/python3.6/site-packages/django/core/handlers/base.py", line 187, in _get_response
    response = self.process_exception_by_middleware(e, request)
  File "/home/ivan/.local/lib/python3.6/site-packages/django/core/handlers/base.py", line 185, in _get_response
    response = wrapped_callback(request, *callback_args, **callback_kwargs)
  File "/home/ivan/.local/lib/python3.6/site-packages/django/views/decorators/csrf.py", line 58, in wrapped_view
    return view_func(*args, **kwargs)
  File "/home/ivan/dbs-proj/comp3335/search/views.py", line 28, in search
    course.id = msg_decrypt(course.id)
  File "/home/ivan/dbs-proj/comp3335/utils/encryption.py", line 34, in msg_decrypt
    enc = base64.b64decode(enc)
  File "/usr/lib/python3.6/base64.py", line 80, in b64decode
    s = _bytes_from_decode_data(s)
  File "/usr/lib/python3.6/base64.py", line 46, in _bytes_from_decode_data
    "string, not %r" % s.__class__.__name__) from None
TypeError: argument should be a bytes-like object or ASCII string, not 'int'
=======
2017-11-29 00:00:47,412:INFO:request course list for dashboard
2017-11-29 00:00:50,278:INFO:request course detail success: course code = COMP1111
2017-11-29 00:00:59,536:INFO:request course list for dashboard
2017-11-29 00:01:04,975:INFO:request course detail success: course code = COMP1111
2017-11-29 00:01:09,574:INFO:insert message: course code = COMP1111, message = and again
2017-11-29 00:01:25,545:INFO:request course list for dashboard
2017-11-29 00:01:29,136:INFO:request course detail success: course code = COMP1111
2017-11-29 00:01:33,556:INFO:insert message: course code = COMP1111, message = we are strong
2017-11-29 00:31:35,269:WARNING:Not Found: /adminb
2017-11-29 00:31:44,851:INFO:request course list for dashboard
2017-11-29 00:41:30,562:INFO:request course list for dashboard
2017-11-29 00:41:31,269:INFO:request course list for dashboard
2017-11-29 00:41:44,239:INFO:request course list for dashboard
2017-11-29 00:42:21,549:INFO:request course list for dashboard
2017-11-29 00:42:21,722:INFO:request course list for dashboard
2017-11-29 00:42:21,887:INFO:request course list for dashboard
2017-11-29 00:42:33,430:INFO:request course list for dashboard
2017-11-29 00:42:46,581:INFO:request course list for dashboard
>>>>>>> 2063b0f418ac0ba29078d79c67faf4a725cca1b9
2017-11-29 01:05:48,162:INFO:request course list for dashboard
2017-11-29 01:07:01,791:INFO:request course list for dashboard
2017-11-29 01:07:04,025:INFO:request course list for dashboard
2017-11-29 01:13:16,110:ERROR:Internal Server Error: /dashboard/
Traceback (most recent call last):
  File "/home/xiating/.local/lib/python3.5/site-packages/django/core/handlers/exception.py", line 41, in inner
    response = get_response(request)
  File "/home/xiating/.local/lib/python3.5/site-packages/django/core/handlers/base.py", line 187, in _get_response
    response = self.process_exception_by_middleware(e, request)
  File "/home/xiating/.local/lib/python3.5/site-packages/django/core/handlers/base.py", line 185, in _get_response
    response = wrapped_callback(request, *callback_args, **callback_kwargs)
  File "/home/xiating/dbsec/comp3335_project/comp3335/dashboard/views.py", line 20, in index
    if not Account.objects.exists(email=authorized):
  File "/home/xiating/.local/lib/python3.5/site-packages/django/db/models/manager.py", line 85, in manager_method
    return getattr(self.get_queryset(), name)(*args, **kwargs)
TypeError: exists() got an unexpected keyword argument 'email'
2017-11-29 01:14:11,323:ERROR:Internal Server Error: /dashboard/
Traceback (most recent call last):
  File "/home/xiating/.local/lib/python3.5/site-packages/django/core/handlers/exception.py", line 41, in inner
    response = get_response(request)
  File "/home/xiating/.local/lib/python3.5/site-packages/django/core/handlers/base.py", line 187, in _get_response
    response = self.process_exception_by_middleware(e, request)
  File "/home/xiating/.local/lib/python3.5/site-packages/django/core/handlers/base.py", line 185, in _get_response
    response = wrapped_callback(request, *callback_args, **callback_kwargs)
  File "/home/xiating/dbsec/comp3335_project/comp3335/dashboard/views.py", line 20, in index
    if not Account.objects.all().exists(email=authorized):
TypeError: exists() got an unexpected keyword argument 'email'
2017-11-29 01:14:46,777:INFO:request course list for dashboard
2017-11-29 01:14:48,893:INFO:request course detail success: course code = COMP1111
2017-11-29 01:16:43,258:INFO:request course list for dashboard
2017-11-29 01:16:45,424:INFO:request course detail success: course code = COMP1111
2017-11-29 01:19:09,288:INFO:request course list for dashboard
