2017-11-27 20:02:11,419:INFO:request course list for dashboard
2017-11-27 20:02:14,590:INFO:request course detail success: course code = COMP3335
2017-11-27 20:05:50,159:ERROR:Internal Server Error: /account/register
Traceback (most recent call last):
  File "/home/xiating/.local/lib/python3.5/site-packages/django/db/backends/utils.py", line 65, in execute
    return self.cursor.execute(sql, params)
  File "/home/xiating/.local/lib/python3.5/site-packages/django/db/backends/mysql/base.py", line 101, in execute
    return self.cursor.execute(query, args)
  File "/home/xiating/.local/lib/python3.5/site-packages/MySQLdb/cursors.py", line 250, in execute
    self.errorhandler(self, exc, value)
  File "/home/xiating/.local/lib/python3.5/site-packages/MySQLdb/connections.py", line 50, in defaulterrorhandler
    raise errorvalue
  File "/home/xiating/.local/lib/python3.5/site-packages/MySQLdb/cursors.py", line 247, in execute
    res = self._query(query)
  File "/home/xiating/.local/lib/python3.5/site-packages/MySQLdb/cursors.py", line 411, in _query
    rowcount = self._do_query(q)
  File "/home/xiating/.local/lib/python3.5/site-packages/MySQLdb/cursors.py", line 374, in _do_query
    db.query(q)
  File "/home/xiating/.local/lib/python3.5/site-packages/MySQLdb/connections.py", line 277, in query
    _mysql.connection.query(self, query)
_mysql_exceptions.DataError: (1406, "Data too long for column 'age' at row 1")

The above exception was the direct cause of the following exception:

Traceback (most recent call last):
  File "/home/xiating/.local/lib/python3.5/site-packages/django/core/handlers/exception.py", line 41, in inner
    response = get_response(request)
  File "/home/xiating/.local/lib/python3.5/site-packages/django/core/handlers/base.py", line 187, in _get_response
    response = self.process_exception_by_middleware(e, request)
  File "/home/xiating/.local/lib/python3.5/site-packages/django/core/handlers/base.py", line 185, in _get_response
    response = wrapped_callback(request, *callback_args, **callback_kwargs)
  File "/home/xiating/.local/lib/python3.5/site-packages/django/views/decorators/csrf.py", line 58, in wrapped_view
    return view_func(*args, **kwargs)
  File "/home/xiating/dbsec/comp3335_project/comp3335/account/views.py", line 32, in register
    acct.save()
  File "/home/xiating/.local/lib/python3.5/site-packages/django/db/models/base.py", line 808, in save
    force_update=force_update, update_fields=update_fields)
  File "/home/xiating/.local/lib/python3.5/site-packages/django/db/models/base.py", line 838, in save_base
    updated = self._save_table(raw, cls, force_insert, force_update, using, update_fields)
  File "/home/xiating/.local/lib/python3.5/site-packages/django/db/models/base.py", line 924, in _save_table
    result = self._do_insert(cls._base_manager, using, fields, update_pk, raw)
  File "/home/xiating/.local/lib/python3.5/site-packages/django/db/models/base.py", line 963, in _do_insert
    using=using, raw=raw)
  File "/home/xiating/.local/lib/python3.5/site-packages/django/db/models/manager.py", line 85, in manager_method
    return getattr(self.get_queryset(), name)(*args, **kwargs)
  File "/home/xiating/.local/lib/python3.5/site-packages/django/db/models/query.py", line 1076, in _insert
    return query.get_compiler(using=using).execute_sql(return_id)
  File "/home/xiating/.local/lib/python3.5/site-packages/django/db/models/sql/compiler.py", line 1107, in execute_sql
    cursor.execute(sql, params)
  File "/home/xiating/.local/lib/python3.5/site-packages/django/db/backends/utils.py", line 80, in execute
    return super(CursorDebugWrapper, self).execute(sql, params)
  File "/home/xiating/.local/lib/python3.5/site-packages/django/db/backends/utils.py", line 65, in execute
    return self.cursor.execute(sql, params)
  File "/home/xiating/.local/lib/python3.5/site-packages/django/db/utils.py", line 94, in __exit__
    six.reraise(dj_exc_type, dj_exc_value, traceback)
  File "/home/xiating/.local/lib/python3.5/site-packages/django/utils/six.py", line 685, in reraise
    raise value.with_traceback(tb)
  File "/home/xiating/.local/lib/python3.5/site-packages/django/db/backends/utils.py", line 65, in execute
    return self.cursor.execute(sql, params)
  File "/home/xiating/.local/lib/python3.5/site-packages/django/db/backends/mysql/base.py", line 101, in execute
    return self.cursor.execute(query, args)
  File "/home/xiating/.local/lib/python3.5/site-packages/MySQLdb/cursors.py", line 250, in execute
    self.errorhandler(self, exc, value)
  File "/home/xiating/.local/lib/python3.5/site-packages/MySQLdb/connections.py", line 50, in defaulterrorhandler
    raise errorvalue
  File "/home/xiating/.local/lib/python3.5/site-packages/MySQLdb/cursors.py", line 247, in execute
    res = self._query(query)
  File "/home/xiating/.local/lib/python3.5/site-packages/MySQLdb/cursors.py", line 411, in _query
    rowcount = self._do_query(q)
  File "/home/xiating/.local/lib/python3.5/site-packages/MySQLdb/cursors.py", line 374, in _do_query
    db.query(q)
  File "/home/xiating/.local/lib/python3.5/site-packages/MySQLdb/connections.py", line 277, in query
    _mysql.connection.query(self, query)
django.db.utils.DataError: (1406, "Data too long for column 'age' at row 1")
2017-11-27 20:26:38,047:INFO:request course list for dashboard
2017-11-27 20:31:35,665:INFO:request course list for dashboard
2017-11-27 20:33:34,911:INFO:request course list for dashboard
2017-11-27 20:33:51,351:INFO:request course list for dashboard
2017-11-27 20:33:58,433:INFO:request course list for dashboard
2017-11-27 20:34:02,945:INFO:request course list for dashboard
2017-11-27 20:38:06,836:INFO:request course detail success: course code = COMP3335
2017-11-27 20:38:21,516:INFO:request course detail success: course code = COMP4431
2017-11-27 20:38:35,902:INFO:insert message: course code = COMP4431, message = 
2017-11-27 20:38:37,144:INFO:insert message: course code = COMP4431, message = 
2017-11-27 20:38:37,425:INFO:insert message: course code = COMP4431, message = 
2017-11-27 20:38:37,706:INFO:insert message: course code = COMP4431, message = 
2017-11-27 20:38:39,457:INFO:insert message: course code = COMP4431, message = sdas
2017-11-27 20:38:40,975:INFO:insert message: course code = COMP4431, message = dsafsd
2017-11-27 20:38:42,062:INFO:insert message: course code = COMP4431, message = 
2017-11-27 20:38:44,458:INFO:insert message: course code = COMP4431, message = ssss
2017-11-27 20:38:55,103:INFO:request course list for dashboard
2017-11-27 20:38:57,194:INFO:request course detail success: course code = COMP3335
2017-11-27 20:39:02,478:INFO:insert message: course code = COMP3335, message = this is shit
2017-11-27 20:39:09,084:INFO:insert message: course code = COMP3335, message = send
2017-11-27 20:39:09,904:INFO:insert message: course code = COMP3335, message = send
2017-11-27 21:04:46,626:ERROR:Internal Server Error: /account/register
Traceback (most recent call last):
  File "/home/xiating/.local/lib/python3.5/site-packages/django/utils/datastructures.py", line 83, in __getitem__
    list_ = super(MultiValueDict, self).__getitem__(key)
KeyError: 'password'

During handling of the above exception, another exception occurred:

Traceback (most recent call last):
  File "/home/xiating/.local/lib/python3.5/site-packages/django/core/handlers/exception.py", line 41, in inner
    response = get_response(request)
  File "/home/xiating/.local/lib/python3.5/site-packages/django/core/handlers/base.py", line 187, in _get_response
    response = self.process_exception_by_middleware(e, request)
  File "/home/xiating/.local/lib/python3.5/site-packages/django/core/handlers/base.py", line 185, in _get_response
    response = wrapped_callback(request, *callback_args, **callback_kwargs)
  File "/home/xiating/.local/lib/python3.5/site-packages/django/views/decorators/csrf.py", line 58, in wrapped_view
    return view_func(*args, **kwargs)
  File "/home/xiating/dbsec/comp3335_project/comp3335/account/views.py", line 14, in register
    pwd1 = request.POST["password"]
  File "/home/xiating/.local/lib/python3.5/site-packages/django/utils/datastructures.py", line 85, in __getitem__
    raise MultiValueDictKeyError(repr(key))
django.utils.datastructures.MultiValueDictKeyError: "'password'"
2017-11-27 21:07:30,421:ERROR:Internal Server Error: /account/register
Traceback (most recent call last):
  File "/home/xiating/.local/lib/python3.5/site-packages/django/core/handlers/exception.py", line 41, in inner
    response = get_response(request)
  File "/home/xiating/.local/lib/python3.5/site-packages/django/core/handlers/base.py", line 187, in _get_response
    response = self.process_exception_by_middleware(e, request)
  File "/home/xiating/.local/lib/python3.5/site-packages/django/core/handlers/base.py", line 185, in _get_response
    response = wrapped_callback(request, *callback_args, **callback_kwargs)
  File "/home/xiating/.local/lib/python3.5/site-packages/django/views/decorators/csrf.py", line 58, in wrapped_view
    return view_func(*args, **kwargs)
  File "/home/xiating/dbsec/comp3335_project/comp3335/account/views.py", line 13, in register
    if not form.is_valid():
UnboundLocalError: local variable 'form' referenced before assignment
2017-11-27 21:09:42,791:ERROR:Internal Server Error: /account/register
Traceback (most recent call last):
  File "/home/xiating/.local/lib/python3.5/site-packages/django/core/handlers/exception.py", line 41, in inner
    response = get_response(request)
  File "/home/xiating/.local/lib/python3.5/site-packages/django/core/handlers/base.py", line 187, in _get_response
    response = self.process_exception_by_middleware(e, request)
  File "/home/xiating/.local/lib/python3.5/site-packages/django/core/handlers/base.py", line 185, in _get_response
    response = wrapped_callback(request, *callback_args, **callback_kwargs)
  File "/home/xiating/.local/lib/python3.5/site-packages/django/views/decorators/csrf.py", line 58, in wrapped_view
    return view_func(*args, **kwargs)
  File "/home/xiating/dbsec/comp3335_project/comp3335/account/views.py", line 16, in register
    if not form.is_valid():
  File "/home/xiating/dbsec/comp3335_project/comp3335/account/forms.py", line 16, in is_valid
    if valid and self.pwd == self.pwd2:
AttributeError: 'RegisterForm' object has no attribute 'pwd'
2017-11-27 21:14:26,049:ERROR:Internal Server Error: /account/register
Traceback (most recent call last):
  File "/home/xiating/.local/lib/python3.5/site-packages/django/core/handlers/exception.py", line 41, in inner
    response = get_response(request)
  File "/home/xiating/.local/lib/python3.5/site-packages/django/core/handlers/base.py", line 187, in _get_response
    response = self.process_exception_by_middleware(e, request)
  File "/home/xiating/.local/lib/python3.5/site-packages/django/core/handlers/base.py", line 185, in _get_response
    response = wrapped_callback(request, *callback_args, **callback_kwargs)
  File "/home/xiating/.local/lib/python3.5/site-packages/django/views/decorators/csrf.py", line 58, in wrapped_view
    return view_func(*args, **kwargs)
  File "/home/xiating/dbsec/comp3335_project/comp3335/account/views.py", line 35, in register
    return render(request, 'account/register', {})
  File "/home/xiating/.local/lib/python3.5/site-packages/django/shortcuts.py", line 30, in render
    content = loader.render_to_string(template_name, context, request, using=using)
  File "/home/xiating/.local/lib/python3.5/site-packages/django/template/loader.py", line 67, in render_to_string
    template = get_template(template_name, using=using)
  File "/home/xiating/.local/lib/python3.5/site-packages/django/template/loader.py", line 25, in get_template
    raise TemplateDoesNotExist(template_name, chain=chain)
django.template.exceptions.TemplateDoesNotExist: account/register
2017-11-27 21:56:46,433:ERROR:Internal Server Error: /account/register
Traceback (most recent call last):
  File "/home/xiating/.local/lib/python3.5/site-packages/django/db/backends/utils.py", line 65, in execute
    return self.cursor.execute(sql, params)
  File "/home/xiating/.local/lib/python3.5/site-packages/django/db/backends/mysql/base.py", line 101, in execute
    return self.cursor.execute(query, args)
  File "/home/xiating/.local/lib/python3.5/site-packages/MySQLdb/cursors.py", line 250, in execute
    self.errorhandler(self, exc, value)
  File "/home/xiating/.local/lib/python3.5/site-packages/MySQLdb/connections.py", line 50, in defaulterrorhandler
    raise errorvalue
  File "/home/xiating/.local/lib/python3.5/site-packages/MySQLdb/cursors.py", line 247, in execute
    res = self._query(query)
  File "/home/xiating/.local/lib/python3.5/site-packages/MySQLdb/cursors.py", line 411, in _query
    rowcount = self._do_query(q)
  File "/home/xiating/.local/lib/python3.5/site-packages/MySQLdb/cursors.py", line 374, in _do_query
    db.query(q)
  File "/home/xiating/.local/lib/python3.5/site-packages/MySQLdb/connections.py", line 277, in query
    _mysql.connection.query(self, query)
_mysql_exceptions.OperationalError: (1054, "Unknown column 'account_account.salt1' in 'field list'")

The above exception was the direct cause of the following exception:

Traceback (most recent call last):
  File "/home/xiating/.local/lib/python3.5/site-packages/django/core/handlers/exception.py", line 41, in inner
    response = get_response(request)
  File "/home/xiating/.local/lib/python3.5/site-packages/django/core/handlers/base.py", line 187, in _get_response
    response = self.process_exception_by_middleware(e, request)
  File "/home/xiating/.local/lib/python3.5/site-packages/django/core/handlers/base.py", line 185, in _get_response
    response = wrapped_callback(request, *callback_args, **callback_kwargs)
  File "/home/xiating/.local/lib/python3.5/site-packages/django/views/decorators/csrf.py", line 58, in wrapped_view
    return view_func(*args, **kwargs)
  File "/home/xiating/dbsec/comp3335_project/comp3335/account/views.py", line 24, in register
    for acct in accts:
  File "/home/xiating/.local/lib/python3.5/site-packages/django/db/models/query.py", line 250, in __iter__
    self._fetch_all()
  File "/home/xiating/.local/lib/python3.5/site-packages/django/db/models/query.py", line 1118, in _fetch_all
    self._result_cache = list(self._iterable_class(self))
  File "/home/xiating/.local/lib/python3.5/site-packages/django/db/models/query.py", line 53, in __iter__
    results = compiler.execute_sql(chunked_fetch=self.chunked_fetch)
  File "/home/xiating/.local/lib/python3.5/site-packages/django/db/models/sql/compiler.py", line 894, in execute_sql
    raise original_exception
  File "/home/xiating/.local/lib/python3.5/site-packages/django/db/models/sql/compiler.py", line 884, in execute_sql
    cursor.execute(sql, params)
  File "/home/xiating/.local/lib/python3.5/site-packages/django/db/backends/utils.py", line 80, in execute
    return super(CursorDebugWrapper, self).execute(sql, params)
  File "/home/xiating/.local/lib/python3.5/site-packages/django/db/backends/utils.py", line 65, in execute
    return self.cursor.execute(sql, params)
  File "/home/xiating/.local/lib/python3.5/site-packages/django/db/utils.py", line 94, in __exit__
    six.reraise(dj_exc_type, dj_exc_value, traceback)
  File "/home/xiating/.local/lib/python3.5/site-packages/django/utils/six.py", line 685, in reraise
    raise value.with_traceback(tb)
  File "/home/xiating/.local/lib/python3.5/site-packages/django/db/backends/utils.py", line 65, in execute
    return self.cursor.execute(sql, params)
  File "/home/xiating/.local/lib/python3.5/site-packages/django/db/backends/mysql/base.py", line 101, in execute
    return self.cursor.execute(query, args)
  File "/home/xiating/.local/lib/python3.5/site-packages/MySQLdb/cursors.py", line 250, in execute
    self.errorhandler(self, exc, value)
  File "/home/xiating/.local/lib/python3.5/site-packages/MySQLdb/connections.py", line 50, in defaulterrorhandler
    raise errorvalue
  File "/home/xiating/.local/lib/python3.5/site-packages/MySQLdb/cursors.py", line 247, in execute
    res = self._query(query)
  File "/home/xiating/.local/lib/python3.5/site-packages/MySQLdb/cursors.py", line 411, in _query
    rowcount = self._do_query(q)
  File "/home/xiating/.local/lib/python3.5/site-packages/MySQLdb/cursors.py", line 374, in _do_query
    db.query(q)
  File "/home/xiating/.local/lib/python3.5/site-packages/MySQLdb/connections.py", line 277, in query
    _mysql.connection.query(self, query)
django.db.utils.OperationalError: (1054, "Unknown column 'account_account.salt1' in 'field list'")
2017-11-27 22:14:37,616:ERROR:Internal Server Error: /account/register
Traceback (most recent call last):
  File "/home/xiating/.local/lib/python3.5/site-packages/django/core/handlers/exception.py", line 41, in inner
    response = get_response(request)
  File "/home/xiating/.local/lib/python3.5/site-packages/django/core/handlers/base.py", line 187, in _get_response
    response = self.process_exception_by_middleware(e, request)
  File "/home/xiating/.local/lib/python3.5/site-packages/django/core/handlers/base.py", line 185, in _get_response
    response = wrapped_callback(request, *callback_args, **callback_kwargs)
  File "/home/xiating/.local/lib/python3.5/site-packages/django/views/decorators/csrf.py", line 58, in wrapped_view
    return view_func(*args, **kwargs)
  File "/home/xiating/dbsec/comp3335_project/comp3335/account/views.py", line 34, in register
    salt = encrypt(salt2, pwd1)
  File "/home/xiating/dbsec/comp3335_project/comp3335/utils/encryption.py", line 47, in encrypt
    key = trim(input_key)
NameError: name 'trim' is not defined
2017-11-27 22:16:04,521:ERROR:Internal Server Error: /account/auth
Traceback (most recent call last):
  File "/home/xiating/.local/lib/python3.5/site-packages/django/core/handlers/exception.py", line 41, in inner
    response = get_response(request)
  File "/home/xiating/.local/lib/python3.5/site-packages/django/core/handlers/base.py", line 187, in _get_response
    response = self.process_exception_by_middleware(e, request)
  File "/home/xiating/.local/lib/python3.5/site-packages/django/core/handlers/base.py", line 185, in _get_response
    response = wrapped_callback(request, *callback_args, **callback_kwargs)
  File "/home/xiating/.local/lib/python3.5/site-packages/django/views/decorators/csrf.py", line 58, in wrapped_view
    return view_func(*args, **kwargs)
  File "/home/xiating/dbsec/comp3335_project/comp3335/account/views.py", line 61, in auth
    if email == username:
NameError: name 'email' is not defined
2017-11-27 22:16:29,573:ERROR:Internal Server Error: /account/auth
Traceback (most recent call last):
  File "/home/xiating/.local/lib/python3.5/site-packages/django/core/handlers/exception.py", line 41, in inner
    response = get_response(request)
  File "/home/xiating/.local/lib/python3.5/site-packages/django/core/handlers/base.py", line 187, in _get_response
    response = self.process_exception_by_middleware(e, request)
  File "/home/xiating/.local/lib/python3.5/site-packages/django/core/handlers/base.py", line 185, in _get_response
    response = wrapped_callback(request, *callback_args, **callback_kwargs)
  File "/home/xiating/.local/lib/python3.5/site-packages/django/views/decorators/csrf.py", line 58, in wrapped_view
    return view_func(*args, **kwargs)
  File "/home/xiating/dbsec/comp3335_project/comp3335/account/views.py", line 64, in auth
    return render(request, '/dashboard', {})
  File "/home/xiating/.local/lib/python3.5/site-packages/django/shortcuts.py", line 30, in render
    content = loader.render_to_string(template_name, context, request, using=using)
  File "/home/xiating/.local/lib/python3.5/site-packages/django/template/loader.py", line 67, in render_to_string
    template = get_template(template_name, using=using)
  File "/home/xiating/.local/lib/python3.5/site-packages/django/template/loader.py", line 25, in get_template
    raise TemplateDoesNotExist(template_name, chain=chain)
django.template.exceptions.TemplateDoesNotExist: /dashboard
2017-11-27 22:16:50,625:ERROR:Internal Server Error: /account/auth
Traceback (most recent call last):
  File "/home/xiating/.local/lib/python3.5/site-packages/django/core/handlers/exception.py", line 41, in inner
    response = get_response(request)
  File "/home/xiating/.local/lib/python3.5/site-packages/django/core/handlers/base.py", line 187, in _get_response
    response = self.process_exception_by_middleware(e, request)
  File "/home/xiating/.local/lib/python3.5/site-packages/django/core/handlers/base.py", line 185, in _get_response
    response = wrapped_callback(request, *callback_args, **callback_kwargs)
  File "/home/xiating/.local/lib/python3.5/site-packages/django/views/decorators/csrf.py", line 58, in wrapped_view
    return view_func(*args, **kwargs)
  File "/home/xiating/dbsec/comp3335_project/comp3335/account/views.py", line 64, in auth
    return render(request, '/dashboard/', {})
  File "/home/xiating/.local/lib/python3.5/site-packages/django/shortcuts.py", line 30, in render
    content = loader.render_to_string(template_name, context, request, using=using)
  File "/home/xiating/.local/lib/python3.5/site-packages/django/template/loader.py", line 67, in render_to_string
    template = get_template(template_name, using=using)
  File "/home/xiating/.local/lib/python3.5/site-packages/django/template/loader.py", line 25, in get_template
    raise TemplateDoesNotExist(template_name, chain=chain)
django.template.exceptions.TemplateDoesNotExist: /dashboard/
2017-11-27 22:24:35,120:INFO:request course list for dashboard
2017-11-27 22:24:46,253:INFO:request course list for dashboard
2017-11-27 22:24:48,102:INFO:request course list for dashboard
2017-11-27 22:25:58,555:INFO:request course list for dashboard
2017-11-27 23:06:33,446:INFO:request course list for dashboard
2017-11-27 23:08:50,469:ERROR:Internal Server Error: /account/auth
Traceback (most recent call last):
  File "/home/xiating/.local/lib/python3.5/site-packages/django/db/backends/utils.py", line 65, in execute
    return self.cursor.execute(sql, params)
  File "/home/xiating/.local/lib/python3.5/site-packages/django/db/backends/mysql/base.py", line 101, in execute
    return self.cursor.execute(query, args)
  File "/home/xiating/.local/lib/python3.5/site-packages/MySQLdb/cursors.py", line 250, in execute
    self.errorhandler(self, exc, value)
  File "/home/xiating/.local/lib/python3.5/site-packages/MySQLdb/connections.py", line 50, in defaulterrorhandler
    raise errorvalue
  File "/home/xiating/.local/lib/python3.5/site-packages/MySQLdb/cursors.py", line 247, in execute
    res = self._query(query)
  File "/home/xiating/.local/lib/python3.5/site-packages/MySQLdb/cursors.py", line 411, in _query
    rowcount = self._do_query(q)
  File "/home/xiating/.local/lib/python3.5/site-packages/MySQLdb/cursors.py", line 374, in _do_query
    db.query(q)
  File "/home/xiating/.local/lib/python3.5/site-packages/MySQLdb/connections.py", line 277, in query
    _mysql.connection.query(self, query)
_mysql_exceptions.ProgrammingError: (1146, "Table 'DEV.account_account_audit' doesn't exist")

The above exception was the direct cause of the following exception:

Traceback (most recent call last):
  File "/home/xiating/.local/lib/python3.5/site-packages/django/core/handlers/exception.py", line 41, in inner
    response = get_response(request)
  File "/home/xiating/.local/lib/python3.5/site-packages/django/core/handlers/base.py", line 187, in _get_response
    response = self.process_exception_by_middleware(e, request)
  File "/home/xiating/.local/lib/python3.5/site-packages/django/core/handlers/base.py", line 185, in _get_response
    response = wrapped_callback(request, *callback_args, **callback_kwargs)
  File "/home/xiating/.local/lib/python3.5/site-packages/django/views/decorators/csrf.py", line 58, in wrapped_view
    return view_func(*args, **kwargs)
  File "/home/xiating/dbsec/comp3335_project/comp3335/account/views.py", line 63, in auth
    print(p_hist)
  File "/home/xiating/.local/lib/python3.5/site-packages/django/db/models/query.py", line 226, in __repr__
    data = list(self[:REPR_OUTPUT_SIZE + 1])
  File "/home/xiating/.local/lib/python3.5/site-packages/django/db/models/query.py", line 250, in __iter__
    self._fetch_all()
  File "/home/xiating/.local/lib/python3.5/site-packages/django/db/models/query.py", line 1118, in _fetch_all
    self._result_cache = list(self._iterable_class(self))
  File "/home/xiating/.local/lib/python3.5/site-packages/django/db/models/query.py", line 53, in __iter__
    results = compiler.execute_sql(chunked_fetch=self.chunked_fetch)
  File "/home/xiating/.local/lib/python3.5/site-packages/django/db/models/sql/compiler.py", line 894, in execute_sql
    raise original_exception
  File "/home/xiating/.local/lib/python3.5/site-packages/django/db/models/sql/compiler.py", line 884, in execute_sql
    cursor.execute(sql, params)
  File "/home/xiating/.local/lib/python3.5/site-packages/django/db/backends/utils.py", line 80, in execute
    return super(CursorDebugWrapper, self).execute(sql, params)
  File "/home/xiating/.local/lib/python3.5/site-packages/django/db/backends/utils.py", line 65, in execute
    return self.cursor.execute(sql, params)
  File "/home/xiating/.local/lib/python3.5/site-packages/django/db/utils.py", line 94, in __exit__
    six.reraise(dj_exc_type, dj_exc_value, traceback)
  File "/home/xiating/.local/lib/python3.5/site-packages/django/utils/six.py", line 685, in reraise
    raise value.with_traceback(tb)
  File "/home/xiating/.local/lib/python3.5/site-packages/django/db/backends/utils.py", line 65, in execute
    return self.cursor.execute(sql, params)
  File "/home/xiating/.local/lib/python3.5/site-packages/django/db/backends/mysql/base.py", line 101, in execute
    return self.cursor.execute(query, args)
  File "/home/xiating/.local/lib/python3.5/site-packages/MySQLdb/cursors.py", line 250, in execute
    self.errorhandler(self, exc, value)
  File "/home/xiating/.local/lib/python3.5/site-packages/MySQLdb/connections.py", line 50, in defaulterrorhandler
    raise errorvalue
  File "/home/xiating/.local/lib/python3.5/site-packages/MySQLdb/cursors.py", line 247, in execute
    res = self._query(query)
  File "/home/xiating/.local/lib/python3.5/site-packages/MySQLdb/cursors.py", line 411, in _query
    rowcount = self._do_query(q)
  File "/home/xiating/.local/lib/python3.5/site-packages/MySQLdb/cursors.py", line 374, in _do_query
    db.query(q)
  File "/home/xiating/.local/lib/python3.5/site-packages/MySQLdb/connections.py", line 277, in query
    _mysql.connection.query(self, query)
django.db.utils.ProgrammingError: (1146, "Table 'DEV.account_account_audit' doesn't exist")
2017-11-27 23:11:56,456:ERROR:Internal Server Error: /account/auth
Traceback (most recent call last):
  File "/home/xiating/.local/lib/python3.5/site-packages/django/db/backends/utils.py", line 65, in execute
    return self.cursor.execute(sql, params)
  File "/home/xiating/.local/lib/python3.5/site-packages/django/db/backends/mysql/base.py", line 101, in execute
    return self.cursor.execute(query, args)
  File "/home/xiating/.local/lib/python3.5/site-packages/MySQLdb/cursors.py", line 250, in execute
    self.errorhandler(self, exc, value)
  File "/home/xiating/.local/lib/python3.5/site-packages/MySQLdb/connections.py", line 50, in defaulterrorhandler
    raise errorvalue
  File "/home/xiating/.local/lib/python3.5/site-packages/MySQLdb/cursors.py", line 247, in execute
    res = self._query(query)
  File "/home/xiating/.local/lib/python3.5/site-packages/MySQLdb/cursors.py", line 411, in _query
    rowcount = self._do_query(q)
  File "/home/xiating/.local/lib/python3.5/site-packages/MySQLdb/cursors.py", line 374, in _do_query
    db.query(q)
  File "/home/xiating/.local/lib/python3.5/site-packages/MySQLdb/connections.py", line 277, in query
    _mysql.connection.query(self, query)
_mysql_exceptions.ProgrammingError: (1146, "Table 'DEV.account_account_audit' doesn't exist")

The above exception was the direct cause of the following exception:

Traceback (most recent call last):
  File "/home/xiating/.local/lib/python3.5/site-packages/django/core/handlers/exception.py", line 41, in inner
    response = get_response(request)
  File "/home/xiating/.local/lib/python3.5/site-packages/django/core/handlers/base.py", line 187, in _get_response
    response = self.process_exception_by_middleware(e, request)
  File "/home/xiating/.local/lib/python3.5/site-packages/django/core/handlers/base.py", line 185, in _get_response
    response = wrapped_callback(request, *callback_args, **callback_kwargs)
  File "/home/xiating/.local/lib/python3.5/site-packages/django/views/decorators/csrf.py", line 58, in wrapped_view
    return view_func(*args, **kwargs)
  File "/home/xiating/dbsec/comp3335_project/comp3335/account/views.py", line 63, in auth
    print(p_hist)
  File "/home/xiating/.local/lib/python3.5/site-packages/django/db/models/query.py", line 226, in __repr__
    data = list(self[:REPR_OUTPUT_SIZE + 1])
  File "/home/xiating/.local/lib/python3.5/site-packages/django/db/models/query.py", line 250, in __iter__
    self._fetch_all()
  File "/home/xiating/.local/lib/python3.5/site-packages/django/db/models/query.py", line 1118, in _fetch_all
    self._result_cache = list(self._iterable_class(self))
  File "/home/xiating/.local/lib/python3.5/site-packages/django/db/models/query.py", line 53, in __iter__
    results = compiler.execute_sql(chunked_fetch=self.chunked_fetch)
  File "/home/xiating/.local/lib/python3.5/site-packages/django/db/models/sql/compiler.py", line 894, in execute_sql
    raise original_exception
  File "/home/xiating/.local/lib/python3.5/site-packages/django/db/models/sql/compiler.py", line 884, in execute_sql
    cursor.execute(sql, params)
  File "/home/xiating/.local/lib/python3.5/site-packages/django/db/backends/utils.py", line 80, in execute
    return super(CursorDebugWrapper, self).execute(sql, params)
  File "/home/xiating/.local/lib/python3.5/site-packages/django/db/backends/utils.py", line 65, in execute
    return self.cursor.execute(sql, params)
  File "/home/xiating/.local/lib/python3.5/site-packages/django/db/utils.py", line 94, in __exit__
    six.reraise(dj_exc_type, dj_exc_value, traceback)
  File "/home/xiating/.local/lib/python3.5/site-packages/django/utils/six.py", line 685, in reraise
    raise value.with_traceback(tb)
  File "/home/xiating/.local/lib/python3.5/site-packages/django/db/backends/utils.py", line 65, in execute
    return self.cursor.execute(sql, params)
  File "/home/xiating/.local/lib/python3.5/site-packages/django/db/backends/mysql/base.py", line 101, in execute
    return self.cursor.execute(query, args)
  File "/home/xiating/.local/lib/python3.5/site-packages/MySQLdb/cursors.py", line 250, in execute
    self.errorhandler(self, exc, value)
  File "/home/xiating/.local/lib/python3.5/site-packages/MySQLdb/connections.py", line 50, in defaulterrorhandler
    raise errorvalue
  File "/home/xiating/.local/lib/python3.5/site-packages/MySQLdb/cursors.py", line 247, in execute
    res = self._query(query)
  File "/home/xiating/.local/lib/python3.5/site-packages/MySQLdb/cursors.py", line 411, in _query
    rowcount = self._do_query(q)
  File "/home/xiating/.local/lib/python3.5/site-packages/MySQLdb/cursors.py", line 374, in _do_query
    db.query(q)
  File "/home/xiating/.local/lib/python3.5/site-packages/MySQLdb/connections.py", line 277, in query
    _mysql.connection.query(self, query)
django.db.utils.ProgrammingError: (1146, "Table 'DEV.account_account_audit' doesn't exist")
2017-11-27 23:19:23,947:ERROR:Internal Server Error: /account/auth
Traceback (most recent call last):
  File "/home/xiating/.local/lib/python3.5/site-packages/django/db/backends/utils.py", line 65, in execute
    return self.cursor.execute(sql, params)
  File "/home/xiating/.local/lib/python3.5/site-packages/django/db/backends/mysql/base.py", line 101, in execute
    return self.cursor.execute(query, args)
  File "/home/xiating/.local/lib/python3.5/site-packages/MySQLdb/cursors.py", line 250, in execute
    self.errorhandler(self, exc, value)
  File "/home/xiating/.local/lib/python3.5/site-packages/MySQLdb/connections.py", line 50, in defaulterrorhandler
    raise errorvalue
  File "/home/xiating/.local/lib/python3.5/site-packages/MySQLdb/cursors.py", line 247, in execute
    res = self._query(query)
  File "/home/xiating/.local/lib/python3.5/site-packages/MySQLdb/cursors.py", line 411, in _query
    rowcount = self._do_query(q)
  File "/home/xiating/.local/lib/python3.5/site-packages/MySQLdb/cursors.py", line 374, in _do_query
    db.query(q)
  File "/home/xiating/.local/lib/python3.5/site-packages/MySQLdb/connections.py", line 277, in query
    _mysql.connection.query(self, query)
_mysql_exceptions.ProgrammingError: (1146, "Table 'DEV.account_account_audit' doesn't exist")

The above exception was the direct cause of the following exception:

Traceback (most recent call last):
  File "/home/xiating/.local/lib/python3.5/site-packages/django/core/handlers/exception.py", line 41, in inner
    response = get_response(request)
  File "/home/xiating/.local/lib/python3.5/site-packages/django/core/handlers/base.py", line 187, in _get_response
    response = self.process_exception_by_middleware(e, request)
  File "/home/xiating/.local/lib/python3.5/site-packages/django/core/handlers/base.py", line 185, in _get_response
    response = wrapped_callback(request, *callback_args, **callback_kwargs)
  File "/home/xiating/.local/lib/python3.5/site-packages/django/views/decorators/csrf.py", line 58, in wrapped_view
    return view_func(*args, **kwargs)
  File "/home/xiating/dbsec/comp3335_project/comp3335/account/views.py", line 69, in auth
    print(p_hist)
  File "/home/xiating/.local/lib/python3.5/site-packages/django/db/models/query.py", line 226, in __repr__
    data = list(self[:REPR_OUTPUT_SIZE + 1])
  File "/home/xiating/.local/lib/python3.5/site-packages/django/db/models/query.py", line 250, in __iter__
    self._fetch_all()
  File "/home/xiating/.local/lib/python3.5/site-packages/django/db/models/query.py", line 1118, in _fetch_all
    self._result_cache = list(self._iterable_class(self))
  File "/home/xiating/.local/lib/python3.5/site-packages/django/db/models/query.py", line 53, in __iter__
    results = compiler.execute_sql(chunked_fetch=self.chunked_fetch)
  File "/home/xiating/.local/lib/python3.5/site-packages/django/db/models/sql/compiler.py", line 894, in execute_sql
    raise original_exception
  File "/home/xiating/.local/lib/python3.5/site-packages/django/db/models/sql/compiler.py", line 884, in execute_sql
    cursor.execute(sql, params)
  File "/home/xiating/.local/lib/python3.5/site-packages/django/db/backends/utils.py", line 80, in execute
    return super(CursorDebugWrapper, self).execute(sql, params)
  File "/home/xiating/.local/lib/python3.5/site-packages/django/db/backends/utils.py", line 65, in execute
    return self.cursor.execute(sql, params)
  File "/home/xiating/.local/lib/python3.5/site-packages/django/db/utils.py", line 94, in __exit__
    six.reraise(dj_exc_type, dj_exc_value, traceback)
  File "/home/xiating/.local/lib/python3.5/site-packages/django/utils/six.py", line 685, in reraise
    raise value.with_traceback(tb)
  File "/home/xiating/.local/lib/python3.5/site-packages/django/db/backends/utils.py", line 65, in execute
    return self.cursor.execute(sql, params)
  File "/home/xiating/.local/lib/python3.5/site-packages/django/db/backends/mysql/base.py", line 101, in execute
    return self.cursor.execute(query, args)
  File "/home/xiating/.local/lib/python3.5/site-packages/MySQLdb/cursors.py", line 250, in execute
    self.errorhandler(self, exc, value)
  File "/home/xiating/.local/lib/python3.5/site-packages/MySQLdb/connections.py", line 50, in defaulterrorhandler
    raise errorvalue
  File "/home/xiating/.local/lib/python3.5/site-packages/MySQLdb/cursors.py", line 247, in execute
    res = self._query(query)
  File "/home/xiating/.local/lib/python3.5/site-packages/MySQLdb/cursors.py", line 411, in _query
    rowcount = self._do_query(q)
  File "/home/xiating/.local/lib/python3.5/site-packages/MySQLdb/cursors.py", line 374, in _do_query
    db.query(q)
  File "/home/xiating/.local/lib/python3.5/site-packages/MySQLdb/connections.py", line 277, in query
    _mysql.connection.query(self, query)
django.db.utils.ProgrammingError: (1146, "Table 'DEV.account_account_audit' doesn't exist")
2017-11-27 23:31:16,106:INFO:request course list for dashboard
2017-11-27 23:31:30,329:INFO:request course list for dashboard
2017-11-27 23:36:32,656:WARNING:Not Found: /favicon.ico
2017-11-27 23:36:44,740:ERROR:Internal Server Error: /account/register
Traceback (most recent call last):
  File "/home/xiating/.local/lib/python3.5/site-packages/django/core/handlers/exception.py", line 41, in inner
    response = get_response(request)
  File "/home/xiating/.local/lib/python3.5/site-packages/django/core/handlers/base.py", line 187, in _get_response
    response = self.process_exception_by_middleware(e, request)
  File "/home/xiating/.local/lib/python3.5/site-packages/django/core/handlers/base.py", line 185, in _get_response
    response = wrapped_callback(request, *callback_args, **callback_kwargs)
  File "/home/xiating/.local/lib/python3.5/site-packages/django/views/decorators/csrf.py", line 58, in wrapped_view
    return view_func(*args, **kwargs)
  File "/home/xiating/dbsec/comp3335_project/comp3335/account/views.py", line 48, in register
    print(p_hist)
  File "/home/xiating/.local/lib/python3.5/site-packages/django/db/models/query.py", line 229, in __repr__
    return '<%s %r>' % (self.__class__.__name__, data)
  File "/home/xiating/.local/lib/python3.5/site-packages/django/db/models/base.py", line 590, in __repr__
    u = six.text_type(self)
  File "/home/xiating/dbsec/comp3335_project/audit.py", line 149, in <lambda>
    '__str__': lambda self: '%s as of %s' % (self._audit__str__(), self._audit_timestamp),
AttributeError: 'AccountAudit' object has no attribute '_audit__str__'
2017-11-27 23:37:58,524:INFO:request course list for dashboard
2017-11-27 23:38:23,270:INFO:request course list for dashboard
2017-11-27 23:38:31,972:ERROR:Internal Server Error: /account/auth
Traceback (most recent call last):
  File "/home/xiating/.local/lib/python3.5/site-packages/django/core/handlers/exception.py", line 41, in inner
    response = get_response(request)
  File "/home/xiating/.local/lib/python3.5/site-packages/django/core/handlers/base.py", line 187, in _get_response
    response = self.process_exception_by_middleware(e, request)
  File "/home/xiating/.local/lib/python3.5/site-packages/django/core/handlers/base.py", line 185, in _get_response
    response = wrapped_callback(request, *callback_args, **callback_kwargs)
  File "/home/xiating/.local/lib/python3.5/site-packages/django/views/decorators/csrf.py", line 58, in wrapped_view
    return view_func(*args, **kwargs)
  File "/home/xiating/dbsec/comp3335_project/comp3335/account/views.py", line 69, in auth
    print(p_hist)
  File "/home/xiating/.local/lib/python3.5/site-packages/django/db/models/query.py", line 229, in __repr__
    return '<%s %r>' % (self.__class__.__name__, data)
  File "/home/xiating/.local/lib/python3.5/site-packages/django/db/models/base.py", line 590, in __repr__
    u = six.text_type(self)
  File "/home/xiating/dbsec/comp3335_project/audit.py", line 149, in <lambda>
    '__str__': lambda self: '%s as of %s' % (self._audit__str__(), self._audit_timestamp),
AttributeError: 'AccountAudit' object has no attribute '_audit__str__'
2017-11-27 23:40:38,123:INFO:request course list for dashboard
2017-11-27 23:41:49,375:INFO:request course list for dashboard
2017-11-27 23:43:42,201:INFO:request course list for dashboard
2017-11-28 09:45:45,867:INFO:request course list for dashboard
2017-11-28 09:46:22,684:INFO:request course list for dashboard
2017-11-28 09:47:58,038:INFO:request course list for dashboard
2017-11-28 09:48:15,894:INFO:request course list for dashboard
2017-11-28 09:49:46,889:WARNING:Not Found: /courses
2017-11-28 09:49:54,952:INFO:request course list for dashboard
2017-11-28 09:50:55,594:INFO:request course list for dashboard
2017-11-28 09:53:06,322:INFO:request course list for dashboard
2017-11-28 09:54:22,868:INFO:request course list for dashboard
2017-11-28 09:54:31,530:INFO:request course list for dashboard
2017-11-28 10:13:08,398:ERROR:Internal Server Error: /account/
Traceback (most recent call last):
  File "/home/xiating/.local/lib/python3.5/site-packages/django/core/handlers/exception.py", line 41, in inner
    response = get_response(request)
  File "/home/xiating/.local/lib/python3.5/site-packages/django/core/handlers/base.py", line 217, in _get_response
    response = self.process_exception_by_middleware(e, request)
  File "/home/xiating/.local/lib/python3.5/site-packages/django/core/handlers/base.py", line 215, in _get_response
    response = response.render()
  File "/home/xiating/.local/lib/python3.5/site-packages/django/template/response.py", line 107, in render
    self.content = self.rendered_content
  File "/home/xiating/.local/lib/python3.5/site-packages/django/template/response.py", line 82, in rendered_content
    template = self.resolve_template(self.template_name)
  File "/home/xiating/.local/lib/python3.5/site-packages/django/template/response.py", line 64, in resolve_template
    return select_template(template, using=self.using)
  File "/home/xiating/.local/lib/python3.5/site-packages/django/template/loader.py", line 48, in select_template
    return engine.get_template(template_name)
  File "/home/xiating/.local/lib/python3.5/site-packages/django/template/backends/django.py", line 39, in get_template
    return Template(self.engine.get_template(template_name), self)
  File "/home/xiating/.local/lib/python3.5/site-packages/django/template/engine.py", line 162, in get_template
    template, origin = self.find_template(template_name)
  File "/home/xiating/.local/lib/python3.5/site-packages/django/template/engine.py", line 136, in find_template
    name, template_dirs=dirs, skip=skip,
  File "/home/xiating/.local/lib/python3.5/site-packages/django/template/loaders/base.py", line 44, in get_template
    contents, origin, origin.template_name, self.engine,
  File "/home/xiating/.local/lib/python3.5/site-packages/django/template/base.py", line 191, in __init__
    self.nodelist = self.compile_nodelist()
  File "/home/xiating/.local/lib/python3.5/site-packages/django/template/base.py", line 230, in compile_nodelist
    return parser.parse()
  File "/home/xiating/.local/lib/python3.5/site-packages/django/template/base.py", line 515, in parse
    raise self.error(token, e)
  File "/home/xiating/.local/lib/python3.5/site-packages/django/template/base.py", line 513, in parse
    compiled_result = compile_func(self, token)
  File "/home/xiating/.local/lib/python3.5/site-packages/django/template/loader_tags.py", line 312, in do_extends
    nodelist = parser.parse()
  File "/home/xiating/.local/lib/python3.5/site-packages/django/template/base.py", line 515, in parse
    raise self.error(token, e)
  File "/home/xiating/.local/lib/python3.5/site-packages/django/template/base.py", line 513, in parse
    compiled_result = compile_func(self, token)
  File "/home/xiating/.local/lib/python3.5/site-packages/django/template/loader_tags.py", line 255, in do_block
    nodelist = parser.parse(('endblock',))
  File "/home/xiating/.local/lib/python3.5/site-packages/django/template/base.py", line 515, in parse
    raise self.error(token, e)
  File "/home/xiating/.local/lib/python3.5/site-packages/django/template/base.py", line 513, in parse
    compiled_result = compile_func(self, token)
  File "/home/xiating/.local/lib/python3.5/site-packages/django/template/defaulttags.py", line 969, in do_if
    nodelist = parser.parse(('elif', 'else', 'endif'))
  File "/home/xiating/.local/lib/python3.5/site-packages/django/template/base.py", line 486, in parse
    raise self.error(token, e)
  File "/home/xiating/.local/lib/python3.5/site-packages/django/template/base.py", line 484, in parse
    filter_expression = self.compile_filter(token.contents)
  File "/home/xiating/.local/lib/python3.5/site-packages/django/template/base.py", line 600, in compile_filter
    return FilterExpression(token, self)
  File "/home/xiating/.local/lib/python3.5/site-packages/django/template/base.py", line 700, in __init__
    "from '%s'" % (token[upto:], token))
django.template.exceptions.TemplateSyntaxError: Could not parse the remainder: '["err"]' from 'err["err"]'
2017-11-28 10:14:48,669:INFO:request course list for dashboard
2017-11-28 10:41:15,663:INFO:request course list for dashboard
2017-11-28 10:41:18,818:INFO:request course list for dashboard
2017-11-28 10:41:23,132:INFO:request course list for dashboard
2017-11-28 10:41:25,410:INFO:request course list for dashboard
2017-11-28 10:44:07,736:INFO:request course list for dashboard
2017-11-28 11:39:07,750:INFO:request course list for dashboard
2017-11-28 11:39:09,653:INFO:request course list for dashboard
2017-11-28 11:39:29,959:INFO:request course list for dashboard
2017-11-28 11:44:52,321:ERROR:Internal Server Error: /account/register
Traceback (most recent call last):
  File "/home/xiating/.local/lib/python3.5/site-packages/django/core/handlers/exception.py", line 41, in inner
    response = get_response(request)
  File "/home/xiating/.local/lib/python3.5/site-packages/django/core/handlers/base.py", line 187, in _get_response
    response = self.process_exception_by_middleware(e, request)
  File "/home/xiating/.local/lib/python3.5/site-packages/django/core/handlers/base.py", line 185, in _get_response
    response = wrapped_callback(request, *callback_args, **callback_kwargs)
  File "/home/xiating/.local/lib/python3.5/site-packages/django/views/decorators/csrf.py", line 58, in wrapped_view
    return view_func(*args, **kwargs)
  File "/home/xiating/dbsec/comp3335_project/comp3335/account/views.py", line 88, in register
    return render(request, 'dashboard/index.html', {})
  File "/home/xiating/.local/lib/python3.5/site-packages/django/shortcuts.py", line 30, in render
    content = loader.render_to_string(template_name, context, request, using=using)
  File "/home/xiating/.local/lib/python3.5/site-packages/django/template/loader.py", line 67, in render_to_string
    template = get_template(template_name, using=using)
  File "/home/xiating/.local/lib/python3.5/site-packages/django/template/loader.py", line 25, in get_template
    raise TemplateDoesNotExist(template_name, chain=chain)
django.template.exceptions.TemplateDoesNotExist: dashboard/index.html
2017-11-28 12:00:38,955:INFO:request course list for dashboard
2017-11-28 12:01:43,601:ERROR:Internal Server Error: /account/register
Traceback (most recent call last):
  File "/home/xiating/.local/lib/python3.5/site-packages/django/core/handlers/exception.py", line 41, in inner
    response = get_response(request)
  File "/home/xiating/.local/lib/python3.5/site-packages/django/core/handlers/base.py", line 187, in _get_response
    response = self.process_exception_by_middleware(e, request)
  File "/home/xiating/.local/lib/python3.5/site-packages/django/core/handlers/base.py", line 185, in _get_response
    response = wrapped_callback(request, *callback_args, **callback_kwargs)
  File "/home/xiating/.local/lib/python3.5/site-packages/django/views/decorators/csrf.py", line 58, in wrapped_view
    return view_func(*args, **kwargs)
  File "/home/xiating/dbsec/comp3335_project/comp3335/account/views.py", line 89, in register
    return render(request, 'dashboard/index.html', {})
  File "/home/xiating/.local/lib/python3.5/site-packages/django/shortcuts.py", line 30, in render
    content = loader.render_to_string(template_name, context, request, using=using)
  File "/home/xiating/.local/lib/python3.5/site-packages/django/template/loader.py", line 67, in render_to_string
    template = get_template(template_name, using=using)
  File "/home/xiating/.local/lib/python3.5/site-packages/django/template/loader.py", line 25, in get_template
    raise TemplateDoesNotExist(template_name, chain=chain)
django.template.exceptions.TemplateDoesNotExist: dashboard/index.html
2017-11-28 12:02:53,370:ERROR:Internal Server Error: /account/register
Traceback (most recent call last):
  File "/home/xiating/.local/lib/python3.5/site-packages/django/core/handlers/exception.py", line 41, in inner
    response = get_response(request)
  File "/home/xiating/.local/lib/python3.5/site-packages/django/core/handlers/base.py", line 187, in _get_response
    response = self.process_exception_by_middleware(e, request)
  File "/home/xiating/.local/lib/python3.5/site-packages/django/core/handlers/base.py", line 185, in _get_response
    response = wrapped_callback(request, *callback_args, **callback_kwargs)
  File "/home/xiating/.local/lib/python3.5/site-packages/django/views/decorators/csrf.py", line 58, in wrapped_view
    return view_func(*args, **kwargs)
  File "/home/xiating/dbsec/comp3335_project/comp3335/account/views.py", line 89, in register
    return render(request, 'dashboard/index.html', {})
  File "/home/xiating/.local/lib/python3.5/site-packages/django/shortcuts.py", line 30, in render
    content = loader.render_to_string(template_name, context, request, using=using)
  File "/home/xiating/.local/lib/python3.5/site-packages/django/template/loader.py", line 67, in render_to_string
    template = get_template(template_name, using=using)
  File "/home/xiating/.local/lib/python3.5/site-packages/django/template/loader.py", line 25, in get_template
    raise TemplateDoesNotExist(template_name, chain=chain)
django.template.exceptions.TemplateDoesNotExist: dashboard/index.html
2017-11-28 12:13:39,683:ERROR:Internal Server Error: /account/register
Traceback (most recent call last):
  File "/home/xiating/.local/lib/python3.5/site-packages/django/core/handlers/exception.py", line 41, in inner
    response = get_response(request)
  File "/home/xiating/.local/lib/python3.5/site-packages/django/core/handlers/base.py", line 187, in _get_response
    response = self.process_exception_by_middleware(e, request)
  File "/home/xiating/.local/lib/python3.5/site-packages/django/core/handlers/base.py", line 185, in _get_response
    response = wrapped_callback(request, *callback_args, **callback_kwargs)
  File "/home/xiating/.local/lib/python3.5/site-packages/django/views/decorators/csrf.py", line 58, in wrapped_view
    return view_func(*args, **kwargs)
  File "/home/xiating/dbsec/comp3335_project/comp3335/account/views.py", line 89, in register
    return render(request, 'dashboard/index.html', {})
  File "/home/xiating/.local/lib/python3.5/site-packages/django/shortcuts.py", line 30, in render
    content = loader.render_to_string(template_name, context, request, using=using)
  File "/home/xiating/.local/lib/python3.5/site-packages/django/template/loader.py", line 67, in render_to_string
    template = get_template(template_name, using=using)
  File "/home/xiating/.local/lib/python3.5/site-packages/django/template/loader.py", line 25, in get_template
    raise TemplateDoesNotExist(template_name, chain=chain)
django.template.exceptions.TemplateDoesNotExist: dashboard/index.html
2017-11-28 12:15:09,278:ERROR:Internal Server Error: /account/register
Traceback (most recent call last):
  File "/home/xiating/.local/lib/python3.5/site-packages/django/core/handlers/exception.py", line 41, in inner
    response = get_response(request)
  File "/home/xiating/.local/lib/python3.5/site-packages/django/core/handlers/base.py", line 187, in _get_response
    response = self.process_exception_by_middleware(e, request)
  File "/home/xiating/.local/lib/python3.5/site-packages/django/core/handlers/base.py", line 185, in _get_response
    response = wrapped_callback(request, *callback_args, **callback_kwargs)
  File "/home/xiating/.local/lib/python3.5/site-packages/django/views/decorators/csrf.py", line 58, in wrapped_view
    return view_func(*args, **kwargs)
  File "/home/xiating/dbsec/comp3335_project/comp3335/account/views.py", line 89, in register
    return render(request, 'dashboard/index.html', {})
  File "/home/xiating/.local/lib/python3.5/site-packages/django/shortcuts.py", line 30, in render
    content = loader.render_to_string(template_name, context, request, using=using)
  File "/home/xiating/.local/lib/python3.5/site-packages/django/template/loader.py", line 67, in render_to_string
    template = get_template(template_name, using=using)
  File "/home/xiating/.local/lib/python3.5/site-packages/django/template/loader.py", line 25, in get_template
    raise TemplateDoesNotExist(template_name, chain=chain)
django.template.exceptions.TemplateDoesNotExist: dashboard/index.html
2017-11-28 12:16:42,582:ERROR:Internal Server Error: /account/register
Traceback (most recent call last):
  File "/home/xiating/.local/lib/python3.5/site-packages/django/core/handlers/exception.py", line 41, in inner
    response = get_response(request)
  File "/home/xiating/.local/lib/python3.5/site-packages/django/core/handlers/base.py", line 187, in _get_response
    response = self.process_exception_by_middleware(e, request)
  File "/home/xiating/.local/lib/python3.5/site-packages/django/core/handlers/base.py", line 185, in _get_response
    response = wrapped_callback(request, *callback_args, **callback_kwargs)
  File "/home/xiating/.local/lib/python3.5/site-packages/django/views/decorators/csrf.py", line 58, in wrapped_view
    return view_func(*args, **kwargs)
  File "/home/xiating/dbsec/comp3335_project/comp3335/account/views.py", line 89, in register
    return render(request, 'dashboard/index.html', {})
  File "/home/xiating/.local/lib/python3.5/site-packages/django/shortcuts.py", line 30, in render
    content = loader.render_to_string(template_name, context, request, using=using)
  File "/home/xiating/.local/lib/python3.5/site-packages/django/template/loader.py", line 67, in render_to_string
    template = get_template(template_name, using=using)
  File "/home/xiating/.local/lib/python3.5/site-packages/django/template/loader.py", line 25, in get_template
    raise TemplateDoesNotExist(template_name, chain=chain)
django.template.exceptions.TemplateDoesNotExist: dashboard/index.html
2017-11-28 12:17:50,170:ERROR:Internal Server Error: /account/dashboard/index.html
Traceback (most recent call last):
  File "/home/xiating/.local/lib/python3.5/site-packages/django/core/handlers/exception.py", line 41, in inner
    response = get_response(request)
  File "/home/xiating/.local/lib/python3.5/site-packages/django/core/handlers/base.py", line 217, in _get_response
    response = self.process_exception_by_middleware(e, request)
  File "/home/xiating/.local/lib/python3.5/site-packages/django/core/handlers/base.py", line 215, in _get_response
    response = response.render()
  File "/home/xiating/.local/lib/python3.5/site-packages/django/template/response.py", line 107, in render
    self.content = self.rendered_content
  File "/home/xiating/.local/lib/python3.5/site-packages/django/template/response.py", line 82, in rendered_content
    template = self.resolve_template(self.template_name)
  File "/home/xiating/.local/lib/python3.5/site-packages/django/template/response.py", line 64, in resolve_template
    return select_template(template, using=self.using)
  File "/home/xiating/.local/lib/python3.5/site-packages/django/template/loader.py", line 53, in select_template
    raise TemplateDoesNotExist(', '.join(template_name_list), chain=chain)
django.template.exceptions.TemplateDoesNotExist: dashboard/index.html
2017-11-28 12:18:36,312:ERROR:Internal Server Error: /account/register
Traceback (most recent call last):
  File "/home/xiating/.local/lib/python3.5/site-packages/django/core/handlers/exception.py", line 41, in inner
    response = get_response(request)
  File "/home/xiating/.local/lib/python3.5/site-packages/django/core/handlers/base.py", line 187, in _get_response
    response = self.process_exception_by_middleware(e, request)
  File "/home/xiating/.local/lib/python3.5/site-packages/django/core/handlers/base.py", line 185, in _get_response
    response = wrapped_callback(request, *callback_args, **callback_kwargs)
  File "/home/xiating/.local/lib/python3.5/site-packages/django/views/decorators/csrf.py", line 58, in wrapped_view
    return view_func(*args, **kwargs)
  File "/home/xiating/dbsec/comp3335_project/comp3335/account/views.py", line 89, in register
    return render(request, '/dashboard/index.html', {})
  File "/home/xiating/.local/lib/python3.5/site-packages/django/shortcuts.py", line 30, in render
    content = loader.render_to_string(template_name, context, request, using=using)
  File "/home/xiating/.local/lib/python3.5/site-packages/django/template/loader.py", line 67, in render_to_string
    template = get_template(template_name, using=using)
  File "/home/xiating/.local/lib/python3.5/site-packages/django/template/loader.py", line 25, in get_template
    raise TemplateDoesNotExist(template_name, chain=chain)
django.template.exceptions.TemplateDoesNotExist: dashboard/index.html
2017-11-28 12:20:23,995:WARNING:Not Found: /dashboard/index.html
2017-11-28 12:20:37,616:WARNING:Not Found: /dashboard/index.html
2017-11-28 12:21:45,233:INFO:request course list for dashboard
2017-11-28 12:23:50,005:ERROR:Internal Server Error: /account/register
Traceback (most recent call last):
  File "/home/xiating/.local/lib/python3.5/site-packages/django/core/handlers/exception.py", line 41, in inner
    response = get_response(request)
  File "/home/xiating/.local/lib/python3.5/site-packages/django/core/handlers/base.py", line 187, in _get_response
    response = self.process_exception_by_middleware(e, request)
  File "/home/xiating/.local/lib/python3.5/site-packages/django/core/handlers/base.py", line 185, in _get_response
    response = wrapped_callback(request, *callback_args, **callback_kwargs)
  File "/home/xiating/.local/lib/python3.5/site-packages/django/views/decorators/csrf.py", line 58, in wrapped_view
    return view_func(*args, **kwargs)
  File "/home/xiating/dbsec/comp3335_project/comp3335/account/views.py", line 89, in register
    return render(request, '/dashboard/')
  File "/home/xiating/.local/lib/python3.5/site-packages/django/shortcuts.py", line 30, in render
    content = loader.render_to_string(template_name, context, request, using=using)
  File "/home/xiating/.local/lib/python3.5/site-packages/django/template/loader.py", line 67, in render_to_string
    template = get_template(template_name, using=using)
  File "/home/xiating/.local/lib/python3.5/site-packages/django/template/loader.py", line 25, in get_template
    raise TemplateDoesNotExist(template_name, chain=chain)
django.template.exceptions.TemplateDoesNotExist: /dashboard/
2017-11-28 13:22:28,981:WARNING:Not Found: /course
2017-11-28 13:22:38,364:INFO:request course list for dashboard
2017-11-28 13:54:15,842:INFO:request course list for dashboard
2017-11-28 13:54:23,927:INFO:request course list for dashboard
2017-11-28 13:54:46,366:INFO:request course list for dashboard
2017-11-28 13:56:17,569:INFO:request course list for dashboard
2017-11-28 14:39:54,624:INFO:request course list for dashboard
2017-11-28 14:40:09,408:ERROR:Internal Server Error: /admin/account/accountaudit/
Traceback (most recent call last):
  File "/home/xiating/.local/lib/python3.5/site-packages/django/db/models/options.py", line 617, in get_field
    return self.fields_map[field_name]
KeyError: '__str__'

During handling of the above exception, another exception occurred:

Traceback (most recent call last):
  File "/home/xiating/.local/lib/python3.5/site-packages/django/contrib/admin/utils.py", line 283, in lookup_field
    f = _get_non_gfk_field(opts, name)
  File "/home/xiating/.local/lib/python3.5/site-packages/django/contrib/admin/utils.py", line 317, in _get_non_gfk_field
    field = opts.get_field(name)
  File "/home/xiating/.local/lib/python3.5/site-packages/django/db/models/options.py", line 619, in get_field
    raise FieldDoesNotExist("%s has no field named '%s'" % (self.object_name, field_name))
django.core.exceptions.FieldDoesNotExist: AccountAudit has no field named '__str__'

During handling of the above exception, another exception occurred:

Traceback (most recent call last):
  File "/home/xiating/.local/lib/python3.5/site-packages/django/core/handlers/exception.py", line 41, in inner
    response = get_response(request)
  File "/home/xiating/.local/lib/python3.5/site-packages/django/core/handlers/base.py", line 217, in _get_response
    response = self.process_exception_by_middleware(e, request)
  File "/home/xiating/.local/lib/python3.5/site-packages/django/core/handlers/base.py", line 215, in _get_response
    response = response.render()
  File "/home/xiating/.local/lib/python3.5/site-packages/django/template/response.py", line 107, in render
    self.content = self.rendered_content
  File "/home/xiating/.local/lib/python3.5/site-packages/django/template/response.py", line 84, in rendered_content
    content = template.render(context, self._request)
  File "/home/xiating/.local/lib/python3.5/site-packages/django/template/backends/django.py", line 66, in render
    return self.template.render(context)
  File "/home/xiating/.local/lib/python3.5/site-packages/django/template/base.py", line 207, in render
    return self._render(context)
  File "/home/xiating/.local/lib/python3.5/site-packages/django/template/base.py", line 199, in _render
    return self.nodelist.render(context)
  File "/home/xiating/.local/lib/python3.5/site-packages/django/template/base.py", line 990, in render
    bit = node.render_annotated(context)
  File "/home/xiating/.local/lib/python3.5/site-packages/django/template/base.py", line 957, in render_annotated
    return self.render(context)
  File "/home/xiating/.local/lib/python3.5/site-packages/django/template/loader_tags.py", line 177, in render
    return compiled_parent._render(context)
  File "/home/xiating/.local/lib/python3.5/site-packages/django/template/base.py", line 199, in _render
    return self.nodelist.render(context)
  File "/home/xiating/.local/lib/python3.5/site-packages/django/template/base.py", line 990, in render
    bit = node.render_annotated(context)
  File "/home/xiating/.local/lib/python3.5/site-packages/django/template/base.py", line 957, in render_annotated
    return self.render(context)
  File "/home/xiating/.local/lib/python3.5/site-packages/django/template/loader_tags.py", line 177, in render
    return compiled_parent._render(context)
  File "/home/xiating/.local/lib/python3.5/site-packages/django/template/base.py", line 199, in _render
    return self.nodelist.render(context)
  File "/home/xiating/.local/lib/python3.5/site-packages/django/template/base.py", line 990, in render
    bit = node.render_annotated(context)
  File "/home/xiating/.local/lib/python3.5/site-packages/django/template/base.py", line 957, in render_annotated
    return self.render(context)
  File "/home/xiating/.local/lib/python3.5/site-packages/django/template/loader_tags.py", line 72, in render
    result = block.nodelist.render(context)
  File "/home/xiating/.local/lib/python3.5/site-packages/django/template/base.py", line 990, in render
    bit = node.render_annotated(context)
  File "/home/xiating/.local/lib/python3.5/site-packages/django/template/base.py", line 957, in render_annotated
    return self.render(context)
  File "/home/xiating/.local/lib/python3.5/site-packages/django/template/loader_tags.py", line 72, in render
    result = block.nodelist.render(context)
  File "/home/xiating/.local/lib/python3.5/site-packages/django/template/base.py", line 990, in render
    bit = node.render_annotated(context)
  File "/home/xiating/.local/lib/python3.5/site-packages/django/template/base.py", line 957, in render_annotated
    return self.render(context)
  File "/home/xiating/.local/lib/python3.5/site-packages/django/template/library.py", line 225, in render
    _dict = self.func(*resolved_args, **resolved_kwargs)
  File "/home/xiating/.local/lib/python3.5/site-packages/django/contrib/admin/templatetags/admin_list.py", line 340, in result_list
    'results': list(results(cl))}
  File "/home/xiating/.local/lib/python3.5/site-packages/django/contrib/admin/templatetags/admin_list.py", line 316, in results
    yield ResultList(None, items_for_result(cl, res, None))
  File "/home/xiating/.local/lib/python3.5/site-packages/django/contrib/admin/templatetags/admin_list.py", line 307, in __init__
    super(ResultList, self).__init__(*items)
  File "/home/xiating/.local/lib/python3.5/site-packages/django/contrib/admin/templatetags/admin_list.py", line 218, in items_for_result
    f, attr, value = lookup_field(field_name, result, cl.model_admin)
  File "/home/xiating/.local/lib/python3.5/site-packages/django/contrib/admin/utils.py", line 299, in lookup_field
    value = attr()
  File "/home/xiating/dbsec/comp3335_project/audit.py", line 149, in <lambda>
    '__str__': lambda self: '%s as of %s' % (self._audit__str__(), self._audit_timestamp),
  File "/home/xiating/dbsec/comp3335_project/comp3335/account/models.py", line 20, in __str__
    return msg_decrypt(self.email) + " owns " + "password hash: " + self.pwd_hash + ", firstname encrypted: " + self.f_name + ", lastname encrypted: " + self.l_name
NameError: name 'msg_decrypt' is not defined
2017-11-28 14:43:05,559:INFO:request course list for dashboard
2017-11-28 14:43:07,701:INFO:request course detail success: course code = COMP6666
2017-11-28 14:43:41,349:INFO:request course list for dashboard
2017-11-28 14:47:03,722:INFO:request course list for dashboard
2017-11-28 14:48:02,517:INFO:request course list for dashboard
2017-11-28 14:54:33,326:INFO:request course list for dashboard
2017-11-28 14:54:33,375:INFO:request course list for dashboard
2017-11-28 14:55:27,009:INFO:request course list for dashboard
2017-11-28 15:01:07,491:INFO:request course list for dashboard
2017-11-28 15:01:07,692:INFO:request course list for dashboard
2017-11-28 15:01:14,927:ERROR:Internal Server Error: /dashboard/
Traceback (most recent call last):
  File "/home/xiating/.local/lib/python3.5/site-packages/django/db/backends/base/base.py", line 213, in ensure_connection
    self.connect()
  File "/home/xiating/.local/lib/python3.5/site-packages/django/db/backends/base/base.py", line 189, in connect
    self.connection = self.get_new_connection(conn_params)
  File "/home/xiating/.local/lib/python3.5/site-packages/django/db/backends/mysql/base.py", line 274, in get_new_connection
    conn = Database.connect(**conn_params)
  File "/home/xiating/.local/lib/python3.5/site-packages/MySQLdb/__init__.py", line 86, in Connect
    return Connection(*args, **kwargs)
  File "/home/xiating/.local/lib/python3.5/site-packages/MySQLdb/connections.py", line 204, in __init__
    super(Connection, self).__init__(*args, **kwargs2)
_mysql_exceptions.OperationalError: (2003, "Can't connect to MySQL server on '128.199.130.241' (110)")

The above exception was the direct cause of the following exception:

Traceback (most recent call last):
  File "/home/xiating/.local/lib/python3.5/site-packages/django/core/handlers/exception.py", line 41, in inner
    response = get_response(request)
  File "/home/xiating/.local/lib/python3.5/site-packages/django/core/handlers/base.py", line 187, in _get_response
    response = self.process_exception_by_middleware(e, request)
  File "/home/xiating/.local/lib/python3.5/site-packages/django/core/handlers/base.py", line 185, in _get_response
    response = wrapped_callback(request, *callback_args, **callback_kwargs)
  File "/home/xiating/dbsec/comp3335_project/comp3335/dashboard/views.py", line 17, in index
    for c in test_courses:
  File "/home/xiating/.local/lib/python3.5/site-packages/django/db/models/query.py", line 250, in __iter__
    self._fetch_all()
  File "/home/xiating/.local/lib/python3.5/site-packages/django/db/models/query.py", line 1118, in _fetch_all
    self._result_cache = list(self._iterable_class(self))
  File "/home/xiating/.local/lib/python3.5/site-packages/django/db/models/query.py", line 53, in __iter__
    results = compiler.execute_sql(chunked_fetch=self.chunked_fetch)
  File "/home/xiating/.local/lib/python3.5/site-packages/django/db/models/sql/compiler.py", line 882, in execute_sql
    cursor = self.connection.cursor()
  File "/home/xiating/.local/lib/python3.5/site-packages/django/db/backends/base/base.py", line 254, in cursor
    return self._cursor()
  File "/home/xiating/.local/lib/python3.5/site-packages/django/db/backends/base/base.py", line 229, in _cursor
    self.ensure_connection()
  File "/home/xiating/.local/lib/python3.5/site-packages/django/db/backends/base/base.py", line 213, in ensure_connection
    self.connect()
  File "/home/xiating/.local/lib/python3.5/site-packages/django/db/utils.py", line 94, in __exit__
    six.reraise(dj_exc_type, dj_exc_value, traceback)
  File "/home/xiating/.local/lib/python3.5/site-packages/django/utils/six.py", line 685, in reraise
    raise value.with_traceback(tb)
  File "/home/xiating/.local/lib/python3.5/site-packages/django/db/backends/base/base.py", line 213, in ensure_connection
    self.connect()
  File "/home/xiating/.local/lib/python3.5/site-packages/django/db/backends/base/base.py", line 189, in connect
    self.connection = self.get_new_connection(conn_params)
  File "/home/xiating/.local/lib/python3.5/site-packages/django/db/backends/mysql/base.py", line 274, in get_new_connection
    conn = Database.connect(**conn_params)
  File "/home/xiating/.local/lib/python3.5/site-packages/MySQLdb/__init__.py", line 86, in Connect
    return Connection(*args, **kwargs)
  File "/home/xiating/.local/lib/python3.5/site-packages/MySQLdb/connections.py", line 204, in __init__
    super(Connection, self).__init__(*args, **kwargs2)
django.db.utils.OperationalError: (2003, "Can't connect to MySQL server on '128.199.130.241' (110)")
2017-11-28 15:01:22,108:INFO:request course list for dashboard
2017-11-28 15:01:24,104:INFO:request course list for dashboard
2017-11-28 15:01:26,167:INFO:request course list for dashboard
2017-11-28 15:02:43,420:INFO:request course list for dashboard
2017-11-28 15:02:48,678:INFO:request course list for dashboard
2017-11-28 15:22:44,414:ERROR:Internal Server Error: /admin/course/course/
Traceback (most recent call last):
  File "/home/xiating/.local/lib/python3.5/site-packages/django/db/models/options.py", line 617, in get_field
    return self.fields_map[field_name]
KeyError: '__str__'

During handling of the above exception, another exception occurred:

Traceback (most recent call last):
  File "/home/xiating/.local/lib/python3.5/site-packages/django/contrib/admin/utils.py", line 283, in lookup_field
    f = _get_non_gfk_field(opts, name)
  File "/home/xiating/.local/lib/python3.5/site-packages/django/contrib/admin/utils.py", line 317, in _get_non_gfk_field
    field = opts.get_field(name)
  File "/home/xiating/.local/lib/python3.5/site-packages/django/db/models/options.py", line 619, in get_field
    raise FieldDoesNotExist("%s has no field named '%s'" % (self.object_name, field_name))
django.core.exceptions.FieldDoesNotExist: Course has no field named '__str__'

During handling of the above exception, another exception occurred:

Traceback (most recent call last):
  File "/home/xiating/.local/lib/python3.5/site-packages/django/core/handlers/exception.py", line 41, in inner
    response = get_response(request)
  File "/home/xiating/.local/lib/python3.5/site-packages/django/core/handlers/base.py", line 217, in _get_response
    response = self.process_exception_by_middleware(e, request)
  File "/home/xiating/.local/lib/python3.5/site-packages/django/core/handlers/base.py", line 215, in _get_response
    response = response.render()
  File "/home/xiating/.local/lib/python3.5/site-packages/django/template/response.py", line 107, in render
    self.content = self.rendered_content
  File "/home/xiating/.local/lib/python3.5/site-packages/django/template/response.py", line 84, in rendered_content
    content = template.render(context, self._request)
  File "/home/xiating/.local/lib/python3.5/site-packages/django/template/backends/django.py", line 66, in render
    return self.template.render(context)
  File "/home/xiating/.local/lib/python3.5/site-packages/django/template/base.py", line 207, in render
    return self._render(context)
  File "/home/xiating/.local/lib/python3.5/site-packages/django/template/base.py", line 199, in _render
    return self.nodelist.render(context)
  File "/home/xiating/.local/lib/python3.5/site-packages/django/template/base.py", line 990, in render
    bit = node.render_annotated(context)
  File "/home/xiating/.local/lib/python3.5/site-packages/django/template/base.py", line 957, in render_annotated
    return self.render(context)
  File "/home/xiating/.local/lib/python3.5/site-packages/django/template/loader_tags.py", line 177, in render
    return compiled_parent._render(context)
  File "/home/xiating/.local/lib/python3.5/site-packages/django/template/base.py", line 199, in _render
    return self.nodelist.render(context)
  File "/home/xiating/.local/lib/python3.5/site-packages/django/template/base.py", line 990, in render
    bit = node.render_annotated(context)
  File "/home/xiating/.local/lib/python3.5/site-packages/django/template/base.py", line 957, in render_annotated
    return self.render(context)
  File "/home/xiating/.local/lib/python3.5/site-packages/django/template/loader_tags.py", line 177, in render
    return compiled_parent._render(context)
  File "/home/xiating/.local/lib/python3.5/site-packages/django/template/base.py", line 199, in _render
    return self.nodelist.render(context)
  File "/home/xiating/.local/lib/python3.5/site-packages/django/template/base.py", line 990, in render
    bit = node.render_annotated(context)
  File "/home/xiating/.local/lib/python3.5/site-packages/django/template/base.py", line 957, in render_annotated
    return self.render(context)
  File "/home/xiating/.local/lib/python3.5/site-packages/django/template/loader_tags.py", line 72, in render
    result = block.nodelist.render(context)
  File "/home/xiating/.local/lib/python3.5/site-packages/django/template/base.py", line 990, in render
    bit = node.render_annotated(context)
  File "/home/xiating/.local/lib/python3.5/site-packages/django/template/base.py", line 957, in render_annotated
    return self.render(context)
  File "/home/xiating/.local/lib/python3.5/site-packages/django/template/loader_tags.py", line 72, in render
    result = block.nodelist.render(context)
  File "/home/xiating/.local/lib/python3.5/site-packages/django/template/base.py", line 990, in render
    bit = node.render_annotated(context)
  File "/home/xiating/.local/lib/python3.5/site-packages/django/template/base.py", line 957, in render_annotated
    return self.render(context)
  File "/home/xiating/.local/lib/python3.5/site-packages/django/template/library.py", line 225, in render
    _dict = self.func(*resolved_args, **resolved_kwargs)
  File "/home/xiating/.local/lib/python3.5/site-packages/django/contrib/admin/templatetags/admin_list.py", line 340, in result_list
    'results': list(results(cl))}
  File "/home/xiating/.local/lib/python3.5/site-packages/django/contrib/admin/templatetags/admin_list.py", line 316, in results
    yield ResultList(None, items_for_result(cl, res, None))
  File "/home/xiating/.local/lib/python3.5/site-packages/django/contrib/admin/templatetags/admin_list.py", line 307, in __init__
    super(ResultList, self).__init__(*items)
  File "/home/xiating/.local/lib/python3.5/site-packages/django/contrib/admin/templatetags/admin_list.py", line 218, in items_for_result
    f, attr, value = lookup_field(field_name, result, cl.model_admin)
  File "/home/xiating/.local/lib/python3.5/site-packages/django/contrib/admin/utils.py", line 299, in lookup_field
    value = attr()
  File "/home/xiating/dbsec/comp3335_project/comp3335/course/models.py", line 10, in __str__
    return msg_decrypt(self.code) + " "+ msg_decrypt(self.name)
NameError: name 'msg_decrypt' is not defined
