2017-11-28 16:20:54,879:WARNING:Not Found: /admin/a
2017-11-28 16:54:53,721:INFO:request course list for dashboard
2017-11-28 16:54:55,891:WARNING:Not Found: /dashboard/lai shi shi kan
2017-11-28 16:57:56,331:INFO:request course list for dashboard
2017-11-28 16:57:58,453:WARNING:request course detail failed: course code = COMP1111
2017-11-28 16:57:58,891:INFO:request course list for dashboard
2017-11-28 16:58:01,470:WARNING:request course detail failed: course code = COMP1111
2017-11-28 16:58:01,830:INFO:request course list for dashboard
2017-11-28 16:58:08,349:WARNING:request course detail failed: course code = COMP1111
2017-11-28 16:58:08,705:INFO:request course list for dashboard
2017-11-28 17:00:10,951:INFO:request course list for dashboard
2017-11-28 17:00:12,870:WARNING:request course detail failed: course code = COMP1111
2017-11-28 17:00:13,222:INFO:request course list for dashboard
2017-11-28 17:02:45,568:WARNING:request course detail failed: course code = COMP1111
2017-11-28 17:02:45,988:INFO:request course list for dashboard
2017-11-28 17:02:51,724:WARNING:Not Found: /dashboard/coursedetails.html
2017-11-28 17:03:39,126:WARNING:request course detail failed: course code = COMP1111
2017-11-28 17:03:39,478:INFO:request course list for dashboard
2017-11-28 17:03:40,075:WARNING:request course detail failed: course code = COMP1111
2017-11-28 17:03:40,433:INFO:request course list for dashboard
2017-11-28 17:03:42,761:WARNING:request course detail failed: course code = COMP1111
2017-11-28 17:03:42,927:WARNING:request course detail failed: course code = COMP1111
2017-11-28 17:03:43,071:WARNING:request course detail failed: course code = COMP1111
2017-11-28 17:03:43,211:WARNING:request course detail failed: course code = COMP1111
2017-11-28 17:03:43,437:WARNING:request course detail failed: course code = COMP1111
2017-11-28 17:03:43,805:INFO:request course list for dashboard
2017-11-28 17:05:08,205:WARNING:request course detail failed: course code = COMP1111
2017-11-28 17:05:08,573:WARNING:request course detail failed: course code = COMP1111
2017-11-28 17:05:08,925:INFO:request course list for dashboard
2017-11-28 17:05:26,308:WARNING:request course detail failed: course code = COMP1111
2017-11-28 17:05:26,661:INFO:request course list for dashboard
2017-11-28 17:09:19,789:WARNING:request course detail failed: course code = COMP1111
2017-11-28 17:09:20,143:INFO:request course list for dashboard
2017-11-28 17:10:05,424:WARNING:request course detail failed: course code = COMP1111
2017-11-28 17:10:05,786:INFO:request course list for dashboard
2017-11-28 17:10:08,270:WARNING:request course detail failed: course code = COMP1111
2017-11-28 17:10:08,622:INFO:request course list for dashboard
2017-11-28 17:15:25,574:INFO:request course list for dashboard
2017-11-28 17:15:27,581:WARNING:request course detail failed: course code = COMP1111
2017-11-28 17:15:27,917:INFO:request course list for dashboard
2017-11-28 17:15:29,769:WARNING:request course detail failed: course code = COMP1111
2017-11-28 17:15:30,123:INFO:request course list for dashboard
2017-11-28 17:15:40,015:INFO:request course list for dashboard
2017-11-28 17:15:41,490:WARNING:request course detail failed: course code = COMP1111
2017-11-28 17:15:41,855:INFO:request course list for dashboard
2017-11-28 17:17:31,300:INFO:request course list for dashboard
2017-11-28 17:17:44,383:INFO:request course list for dashboard
2017-11-28 17:17:46,460:WARNING:request course detail failed: course code = COMP1111
2017-11-28 17:17:46,808:INFO:request course list for dashboard
2017-11-28 17:28:12,265:WARNING:request course detail failed: course code = COMP1111
2017-11-28 17:28:12,625:INFO:request course list for dashboard
2017-11-28 17:28:14,691:INFO:request course list for dashboard
2017-11-28 17:28:16,760:WARNING:request course detail failed: course code = COMP1111
2017-11-28 17:28:17,094:INFO:request course list for dashboard
2017-11-28 17:42:58,157:ERROR:Internal Server Error: /account/auth
Traceback (most recent call last):
  File "/home/ivan/.local/lib/python3.6/site-packages/django/db/backends/base/base.py", line 213, in ensure_connection
    self.connect()
  File "/home/ivan/.local/lib/python3.6/site-packages/django/db/backends/base/base.py", line 189, in connect
    self.connection = self.get_new_connection(conn_params)
  File "/home/ivan/.local/lib/python3.6/site-packages/django/db/backends/mysql/base.py", line 274, in get_new_connection
    conn = Database.connect(**conn_params)
  File "/home/ivan/.local/lib/python3.6/site-packages/MySQLdb/__init__.py", line 86, in Connect
    return Connection(*args, **kwargs)
  File "/home/ivan/.local/lib/python3.6/site-packages/MySQLdb/connections.py", line 204, in __init__
    super(Connection, self).__init__(*args, **kwargs2)
_mysql_exceptions.OperationalError: (2003, "Can't connect to MySQL server on '128.199.130.241' (111)")

The above exception was the direct cause of the following exception:

Traceback (most recent call last):
  File "/home/ivan/.local/lib/python3.6/site-packages/django/core/handlers/exception.py", line 41, in inner
    response = get_response(request)
  File "/home/ivan/.local/lib/python3.6/site-packages/django/core/handlers/base.py", line 187, in _get_response
    response = self.process_exception_by_middleware(e, request)
  File "/home/ivan/.local/lib/python3.6/site-packages/django/core/handlers/base.py", line 185, in _get_response
    response = wrapped_callback(request, *callback_args, **callback_kwargs)
  File "/home/ivan/.local/lib/python3.6/site-packages/django/views/decorators/csrf.py", line 58, in wrapped_view
    return view_func(*args, **kwargs)
  File "/home/ivan/dbs-proj/comp3335/account/views.py", line 96, in auth
    for acct in accts:
  File "/home/ivan/.local/lib/python3.6/site-packages/django/db/models/query.py", line 250, in __iter__
    self._fetch_all()
  File "/home/ivan/.local/lib/python3.6/site-packages/django/db/models/query.py", line 1118, in _fetch_all
    self._result_cache = list(self._iterable_class(self))
  File "/home/ivan/.local/lib/python3.6/site-packages/django/db/models/query.py", line 53, in __iter__
    results = compiler.execute_sql(chunked_fetch=self.chunked_fetch)
  File "/home/ivan/.local/lib/python3.6/site-packages/django/db/models/sql/compiler.py", line 882, in execute_sql
    cursor = self.connection.cursor()
  File "/home/ivan/.local/lib/python3.6/site-packages/django/db/backends/base/base.py", line 254, in cursor
    return self._cursor()
  File "/home/ivan/.local/lib/python3.6/site-packages/django/db/backends/base/base.py", line 229, in _cursor
    self.ensure_connection()
  File "/home/ivan/.local/lib/python3.6/site-packages/django/db/backends/base/base.py", line 213, in ensure_connection
    self.connect()
  File "/home/ivan/.local/lib/python3.6/site-packages/django/db/utils.py", line 94, in __exit__
    six.reraise(dj_exc_type, dj_exc_value, traceback)
  File "/home/ivan/.local/lib/python3.6/site-packages/django/utils/six.py", line 685, in reraise
    raise value.with_traceback(tb)
  File "/home/ivan/.local/lib/python3.6/site-packages/django/db/backends/base/base.py", line 213, in ensure_connection
    self.connect()
  File "/home/ivan/.local/lib/python3.6/site-packages/django/db/backends/base/base.py", line 189, in connect
    self.connection = self.get_new_connection(conn_params)
  File "/home/ivan/.local/lib/python3.6/site-packages/django/db/backends/mysql/base.py", line 274, in get_new_connection
    conn = Database.connect(**conn_params)
  File "/home/ivan/.local/lib/python3.6/site-packages/MySQLdb/__init__.py", line 86, in Connect
    return Connection(*args, **kwargs)
  File "/home/ivan/.local/lib/python3.6/site-packages/MySQLdb/connections.py", line 204, in __init__
    super(Connection, self).__init__(*args, **kwargs2)
django.db.utils.OperationalError: (2003, "Can't connect to MySQL server on '128.199.130.241' (111)")
2017-11-28 17:43:11,861:ERROR:Internal Server Error: /account/auth
Traceback (most recent call last):
  File "/home/ivan/.local/lib/python3.6/site-packages/django/db/backends/base/base.py", line 213, in ensure_connection
    self.connect()
  File "/home/ivan/.local/lib/python3.6/site-packages/django/db/backends/base/base.py", line 189, in connect
    self.connection = self.get_new_connection(conn_params)
  File "/home/ivan/.local/lib/python3.6/site-packages/django/db/backends/mysql/base.py", line 274, in get_new_connection
    conn = Database.connect(**conn_params)
  File "/home/ivan/.local/lib/python3.6/site-packages/MySQLdb/__init__.py", line 86, in Connect
    return Connection(*args, **kwargs)
  File "/home/ivan/.local/lib/python3.6/site-packages/MySQLdb/connections.py", line 204, in __init__
    super(Connection, self).__init__(*args, **kwargs2)
_mysql_exceptions.OperationalError: (2003, "Can't connect to MySQL server on '128.199.130.241' (111)")

The above exception was the direct cause of the following exception:

Traceback (most recent call last):
  File "/home/ivan/.local/lib/python3.6/site-packages/django/core/handlers/exception.py", line 41, in inner
    response = get_response(request)
  File "/home/ivan/.local/lib/python3.6/site-packages/django/core/handlers/base.py", line 187, in _get_response
    response = self.process_exception_by_middleware(e, request)
  File "/home/ivan/.local/lib/python3.6/site-packages/django/core/handlers/base.py", line 185, in _get_response
    response = wrapped_callback(request, *callback_args, **callback_kwargs)
  File "/home/ivan/.local/lib/python3.6/site-packages/django/views/decorators/csrf.py", line 58, in wrapped_view
    return view_func(*args, **kwargs)
  File "/home/ivan/dbs-proj/comp3335/account/views.py", line 96, in auth
    for acct in accts:
  File "/home/ivan/.local/lib/python3.6/site-packages/django/db/models/query.py", line 250, in __iter__
    self._fetch_all()
  File "/home/ivan/.local/lib/python3.6/site-packages/django/db/models/query.py", line 1118, in _fetch_all
    self._result_cache = list(self._iterable_class(self))
  File "/home/ivan/.local/lib/python3.6/site-packages/django/db/models/query.py", line 53, in __iter__
    results = compiler.execute_sql(chunked_fetch=self.chunked_fetch)
  File "/home/ivan/.local/lib/python3.6/site-packages/django/db/models/sql/compiler.py", line 882, in execute_sql
    cursor = self.connection.cursor()
  File "/home/ivan/.local/lib/python3.6/site-packages/django/db/backends/base/base.py", line 254, in cursor
    return self._cursor()
  File "/home/ivan/.local/lib/python3.6/site-packages/django/db/backends/base/base.py", line 229, in _cursor
    self.ensure_connection()
  File "/home/ivan/.local/lib/python3.6/site-packages/django/db/backends/base/base.py", line 213, in ensure_connection
    self.connect()
  File "/home/ivan/.local/lib/python3.6/site-packages/django/db/utils.py", line 94, in __exit__
    six.reraise(dj_exc_type, dj_exc_value, traceback)
  File "/home/ivan/.local/lib/python3.6/site-packages/django/utils/six.py", line 685, in reraise
    raise value.with_traceback(tb)
  File "/home/ivan/.local/lib/python3.6/site-packages/django/db/backends/base/base.py", line 213, in ensure_connection
    self.connect()
  File "/home/ivan/.local/lib/python3.6/site-packages/django/db/backends/base/base.py", line 189, in connect
    self.connection = self.get_new_connection(conn_params)
  File "/home/ivan/.local/lib/python3.6/site-packages/django/db/backends/mysql/base.py", line 274, in get_new_connection
    conn = Database.connect(**conn_params)
  File "/home/ivan/.local/lib/python3.6/site-packages/MySQLdb/__init__.py", line 86, in Connect
    return Connection(*args, **kwargs)
  File "/home/ivan/.local/lib/python3.6/site-packages/MySQLdb/connections.py", line 204, in __init__
    super(Connection, self).__init__(*args, **kwargs2)
django.db.utils.OperationalError: (2003, "Can't connect to MySQL server on '128.199.130.241' (110)")
2017-11-28 15:01:22,108:INFO:request course list for dashboard
2017-11-28 15:01:24,104:INFO:request course list for dashboard
2017-11-28 15:01:26,167:INFO:request course list for dashboard
2017-11-28 15:02:43,420:INFO:request course list for dashboard
2017-11-28 15:02:48,678:INFO:request course list for dashboard
2017-11-28 15:22:44,414:ERROR:Internal Server Error: /admin/course/course/
Traceback (most recent call last):
  File "/home/xiating/.local/lib/python3.5/site-packages/django/db/models/options.py", line 617, in get_field
    return self.fields_map[field_name]
KeyError: '__str__'

During handling of the above exception, another exception occurred:

Traceback (most recent call last):
  File "/home/xiating/.local/lib/python3.5/site-packages/django/contrib/admin/utils.py", line 283, in lookup_field
    f = _get_non_gfk_field(opts, name)
  File "/home/xiating/.local/lib/python3.5/site-packages/django/contrib/admin/utils.py", line 317, in _get_non_gfk_field
    field = opts.get_field(name)
  File "/home/xiating/.local/lib/python3.5/site-packages/django/db/models/options.py", line 619, in get_field
    raise FieldDoesNotExist("%s has no field named '%s'" % (self.object_name, field_name))
django.core.exceptions.FieldDoesNotExist: Course has no field named '__str__'

During handling of the above exception, another exception occurred:

Traceback (most recent call last):
  File "/home/xiating/.local/lib/python3.5/site-packages/django/core/handlers/exception.py", line 41, in inner
    response = get_response(request)
  File "/home/xiating/.local/lib/python3.5/site-packages/django/core/handlers/base.py", line 217, in _get_response
    response = self.process_exception_by_middleware(e, request)
  File "/home/xiating/.local/lib/python3.5/site-packages/django/core/handlers/base.py", line 215, in _get_response
    response = response.render()
  File "/home/xiating/.local/lib/python3.5/site-packages/django/template/response.py", line 107, in render
    self.content = self.rendered_content
  File "/home/xiating/.local/lib/python3.5/site-packages/django/template/response.py", line 84, in rendered_content
    content = template.render(context, self._request)
  File "/home/xiating/.local/lib/python3.5/site-packages/django/template/backends/django.py", line 66, in render
    return self.template.render(context)
  File "/home/xiating/.local/lib/python3.5/site-packages/django/template/base.py", line 207, in render
    return self._render(context)
  File "/home/xiating/.local/lib/python3.5/site-packages/django/template/base.py", line 199, in _render
    return self.nodelist.render(context)
  File "/home/xiating/.local/lib/python3.5/site-packages/django/template/base.py", line 990, in render
    bit = node.render_annotated(context)
  File "/home/xiating/.local/lib/python3.5/site-packages/django/template/base.py", line 957, in render_annotated
    return self.render(context)
  File "/home/xiating/.local/lib/python3.5/site-packages/django/template/loader_tags.py", line 177, in render
    return compiled_parent._render(context)
  File "/home/xiating/.local/lib/python3.5/site-packages/django/template/base.py", line 199, in _render
    return self.nodelist.render(context)
  File "/home/xiating/.local/lib/python3.5/site-packages/django/template/base.py", line 990, in render
    bit = node.render_annotated(context)
  File "/home/xiating/.local/lib/python3.5/site-packages/django/template/base.py", line 957, in render_annotated
    return self.render(context)
  File "/home/xiating/.local/lib/python3.5/site-packages/django/template/loader_tags.py", line 177, in render
    return compiled_parent._render(context)
  File "/home/xiating/.local/lib/python3.5/site-packages/django/template/base.py", line 199, in _render
    return self.nodelist.render(context)
  File "/home/xiating/.local/lib/python3.5/site-packages/django/template/base.py", line 990, in render
    bit = node.render_annotated(context)
  File "/home/xiating/.local/lib/python3.5/site-packages/django/template/base.py", line 957, in render_annotated
    return self.render(context)
  File "/home/xiating/.local/lib/python3.5/site-packages/django/template/loader_tags.py", line 72, in render
    result = block.nodelist.render(context)
  File "/home/xiating/.local/lib/python3.5/site-packages/django/template/base.py", line 990, in render
    bit = node.render_annotated(context)
  File "/home/xiating/.local/lib/python3.5/site-packages/django/template/base.py", line 957, in render_annotated
    return self.render(context)
  File "/home/xiating/.local/lib/python3.5/site-packages/django/template/loader_tags.py", line 72, in render
    result = block.nodelist.render(context)
  File "/home/xiating/.local/lib/python3.5/site-packages/django/template/base.py", line 990, in render
    bit = node.render_annotated(context)
  File "/home/xiating/.local/lib/python3.5/site-packages/django/template/base.py", line 957, in render_annotated
    return self.render(context)
  File "/home/xiating/.local/lib/python3.5/site-packages/django/template/library.py", line 225, in render
    _dict = self.func(*resolved_args, **resolved_kwargs)
  File "/home/xiating/.local/lib/python3.5/site-packages/django/contrib/admin/templatetags/admin_list.py", line 340, in result_list
    'results': list(results(cl))}
  File "/home/xiating/.local/lib/python3.5/site-packages/django/contrib/admin/templatetags/admin_list.py", line 316, in results
    yield ResultList(None, items_for_result(cl, res, None))
  File "/home/xiating/.local/lib/python3.5/site-packages/django/contrib/admin/templatetags/admin_list.py", line 307, in __init__
    super(ResultList, self).__init__(*items)
  File "/home/xiating/.local/lib/python3.5/site-packages/django/contrib/admin/templatetags/admin_list.py", line 218, in items_for_result
    f, attr, value = lookup_field(field_name, result, cl.model_admin)
  File "/home/xiating/.local/lib/python3.5/site-packages/django/contrib/admin/utils.py", line 299, in lookup_field
    value = attr()
  File "/home/xiating/dbsec/comp3335_project/comp3335/course/models.py", line 10, in __str__
    return msg_decrypt(self.code) + " "+ msg_decrypt(self.name)
NameError: name 'msg_decrypt' is not defined
2017-11-28 16:07:23,998:ERROR:Internal Server Error: /admin/course/course/add/
Traceback (most recent call last):
  File "/home/xiating/.local/lib/python3.5/site-packages/django/db/backends/utils.py", line 65, in execute
    return self.cursor.execute(sql, params)
  File "/home/xiating/.local/lib/python3.5/site-packages/django/db/backends/mysql/base.py", line 101, in execute
    return self.cursor.execute(query, args)
  File "/home/xiating/.local/lib/python3.5/site-packages/MySQLdb/cursors.py", line 250, in execute
    self.errorhandler(self, exc, value)
  File "/home/xiating/.local/lib/python3.5/site-packages/MySQLdb/connections.py", line 50, in defaulterrorhandler
    raise errorvalue
  File "/home/xiating/.local/lib/python3.5/site-packages/MySQLdb/cursors.py", line 247, in execute
    res = self._query(query)
  File "/home/xiating/.local/lib/python3.5/site-packages/MySQLdb/cursors.py", line 411, in _query
    rowcount = self._do_query(q)
  File "/home/xiating/.local/lib/python3.5/site-packages/MySQLdb/cursors.py", line 374, in _do_query
    db.query(q)
  File "/home/xiating/.local/lib/python3.5/site-packages/MySQLdb/connections.py", line 277, in query
    _mysql.connection.query(self, query)
_mysql_exceptions.DataError: (1406, "Data too long for column 'code' at row 1")

The above exception was the direct cause of the following exception:

Traceback (most recent call last):
  File "/home/xiating/.local/lib/python3.5/site-packages/django/core/handlers/exception.py", line 41, in inner
    response = get_response(request)
  File "/home/xiating/.local/lib/python3.5/site-packages/django/core/handlers/base.py", line 187, in _get_response
    response = self.process_exception_by_middleware(e, request)
  File "/home/xiating/.local/lib/python3.5/site-packages/django/core/handlers/base.py", line 185, in _get_response
    response = wrapped_callback(request, *callback_args, **callback_kwargs)
  File "/home/xiating/.local/lib/python3.5/site-packages/django/contrib/admin/options.py", line 551, in wrapper
    return self.admin_site.admin_view(view)(*args, **kwargs)
  File "/home/xiating/.local/lib/python3.5/site-packages/django/utils/decorators.py", line 149, in _wrapped_view
    response = view_func(request, *args, **kwargs)
  File "/home/xiating/.local/lib/python3.5/site-packages/django/views/decorators/cache.py", line 57, in _wrapped_view_func
    response = view_func(request, *args, **kwargs)
  File "/home/xiating/.local/lib/python3.5/site-packages/django/contrib/admin/sites.py", line 224, in inner
    return view(request, *args, **kwargs)
  File "/home/xiating/.local/lib/python3.5/site-packages/django/contrib/admin/options.py", line 1508, in add_view
    return self.changeform_view(request, None, form_url, extra_context)
  File "/home/xiating/.local/lib/python3.5/site-packages/django/utils/decorators.py", line 67, in _wrapper
    return bound_func(*args, **kwargs)
  File "/home/xiating/.local/lib/python3.5/site-packages/django/utils/decorators.py", line 149, in _wrapped_view
    response = view_func(request, *args, **kwargs)
  File "/home/xiating/.local/lib/python3.5/site-packages/django/utils/decorators.py", line 63, in bound_func
    return func.__get__(self, type(self))(*args2, **kwargs2)
  File "/home/xiating/.local/lib/python3.5/site-packages/django/contrib/admin/options.py", line 1408, in changeform_view
    return self._changeform_view(request, object_id, form_url, extra_context)
  File "/home/xiating/.local/lib/python3.5/site-packages/django/contrib/admin/options.py", line 1448, in _changeform_view
    self.save_model(request, new_object, form, not add)
  File "/home/xiating/dbsec/comp3335_project/comp3335/course/admin.py", line 16, in save_model
    obj.save()
  File "/home/xiating/.local/lib/python3.5/site-packages/django/db/models/base.py", line 808, in save
    force_update=force_update, update_fields=update_fields)
  File "/home/xiating/.local/lib/python3.5/site-packages/django/db/models/base.py", line 838, in save_base
    updated = self._save_table(raw, cls, force_insert, force_update, using, update_fields)
  File "/home/xiating/.local/lib/python3.5/site-packages/django/db/models/base.py", line 924, in _save_table
    result = self._do_insert(cls._base_manager, using, fields, update_pk, raw)
  File "/home/xiating/.local/lib/python3.5/site-packages/django/db/models/base.py", line 963, in _do_insert
    using=using, raw=raw)
  File "/home/xiating/.local/lib/python3.5/site-packages/django/db/models/manager.py", line 85, in manager_method
    return getattr(self.get_queryset(), name)(*args, **kwargs)
  File "/home/xiating/.local/lib/python3.5/site-packages/django/db/models/query.py", line 1076, in _insert
    return query.get_compiler(using=using).execute_sql(return_id)
  File "/home/xiating/.local/lib/python3.5/site-packages/django/db/models/sql/compiler.py", line 1107, in execute_sql
    cursor.execute(sql, params)
  File "/home/xiating/.local/lib/python3.5/site-packages/django/db/backends/utils.py", line 80, in execute
    return super(CursorDebugWrapper, self).execute(sql, params)
  File "/home/xiating/.local/lib/python3.5/site-packages/django/db/backends/utils.py", line 65, in execute
    return self.cursor.execute(sql, params)
  File "/home/xiating/.local/lib/python3.5/site-packages/django/db/utils.py", line 94, in __exit__
    six.reraise(dj_exc_type, dj_exc_value, traceback)
  File "/home/xiating/.local/lib/python3.5/site-packages/django/utils/six.py", line 685, in reraise
    raise value.with_traceback(tb)
  File "/home/xiating/.local/lib/python3.5/site-packages/django/db/backends/utils.py", line 65, in execute
    return self.cursor.execute(sql, params)
  File "/home/xiating/.local/lib/python3.5/site-packages/django/db/backends/mysql/base.py", line 101, in execute
    return self.cursor.execute(query, args)
  File "/home/xiating/.local/lib/python3.5/site-packages/MySQLdb/cursors.py", line 250, in execute
    self.errorhandler(self, exc, value)
  File "/home/xiating/.local/lib/python3.5/site-packages/MySQLdb/connections.py", line 50, in defaulterrorhandler
    raise errorvalue
  File "/home/xiating/.local/lib/python3.5/site-packages/MySQLdb/cursors.py", line 247, in execute
    res = self._query(query)
  File "/home/xiating/.local/lib/python3.5/site-packages/MySQLdb/cursors.py", line 411, in _query
    rowcount = self._do_query(q)
  File "/home/xiating/.local/lib/python3.5/site-packages/MySQLdb/cursors.py", line 374, in _do_query
    db.query(q)
  File "/home/xiating/.local/lib/python3.5/site-packages/MySQLdb/connections.py", line 277, in query
    _mysql.connection.query(self, query)
django.db.utils.DataError: (1406, "Data too long for column 'code' at row 1")
2017-11-28 16:10:22,191:INFO:request course list for dashboard
2017-11-28 16:10:26,028:WARNING:Not Found: /dashboard/lai shi shi kan
2017-11-28 16:13:03,584:INFO:request course list for dashboard
2017-11-28 16:13:35,518:INFO:request course list for dashboard
2017-11-28 16:21:44,497:INFO:request course list for dashboard
2017-11-28 16:22:25,577:WARNING:Not Found: /dashboard/lai shi shi kan
2017-11-28 16:52:26,455:INFO:request course list for dashboard
2017-11-28 16:52:27,154:WARNING:Not Found: /favicon.ico
2017-11-28 16:52:31,064:WARNING:Not Found: /dashboard/lai shi shi kan
2017-11-28 16:54:12,832:INFO:request course list for dashboard
2017-11-28 16:54:14,172:WARNING:Not Found: /dashboard/lai shi shi kan
2017-11-28 16:54:53,182:INFO:request course list for dashboard
2017-11-28 16:54:58,240:WARNING:Not Found: /dashboard/lai shi shi kan
2017-11-28 16:55:21,340:INFO:request course list for dashboard
2017-11-28 16:55:23,967:WARNING:Not Found: /dashboard/lai shi shi kan
2017-11-28 16:56:56,575:INFO:request course list for dashboard
2017-11-28 16:56:58,859:WARNING:request course detail failed: course code = COMP1111
2017-11-28 16:56:59,255:INFO:request course list for dashboard
2017-11-28 16:57:02,693:WARNING:request course detail failed: course code = COMP1111
2017-11-28 16:57:03,075:INFO:request course list for dashboard
2017-11-28 16:57:03,794:WARNING:request course detail failed: course code = COMP1111
2017-11-28 16:57:04,188:INFO:request course list for dashboard
2017-11-28 16:57:09,065:WARNING:request course detail failed: course code = COMP1111
2017-11-28 16:57:09,450:INFO:request course list for dashboard
2017-11-28 17:02:04,393:ERROR:Internal Server Error: /admin/course/course/add/
Traceback (most recent call last):
  File "/home/xiating/.local/lib/python3.5/site-packages/django/core/handlers/exception.py", line 41, in inner
    response = get_response(request)
  File "/home/xiating/.local/lib/python3.5/site-packages/django/core/handlers/base.py", line 187, in _get_response
    response = self.process_exception_by_middleware(e, request)
  File "/home/xiating/.local/lib/python3.5/site-packages/django/core/handlers/base.py", line 185, in _get_response
    response = wrapped_callback(request, *callback_args, **callback_kwargs)
  File "/home/xiating/.local/lib/python3.5/site-packages/django/contrib/admin/options.py", line 551, in wrapper
    return self.admin_site.admin_view(view)(*args, **kwargs)
  File "/home/xiating/.local/lib/python3.5/site-packages/django/utils/decorators.py", line 149, in _wrapped_view
    response = view_func(request, *args, **kwargs)
  File "/home/xiating/.local/lib/python3.5/site-packages/django/views/decorators/cache.py", line 57, in _wrapped_view_func
    response = view_func(request, *args, **kwargs)
  File "/home/xiating/.local/lib/python3.5/site-packages/django/contrib/admin/sites.py", line 224, in inner
    return view(request, *args, **kwargs)
  File "/home/xiating/.local/lib/python3.5/site-packages/django/contrib/admin/options.py", line 1508, in add_view
    return self.changeform_view(request, None, form_url, extra_context)
  File "/home/xiating/.local/lib/python3.5/site-packages/django/utils/decorators.py", line 67, in _wrapper
    return bound_func(*args, **kwargs)
  File "/home/xiating/.local/lib/python3.5/site-packages/django/utils/decorators.py", line 149, in _wrapped_view
    response = view_func(request, *args, **kwargs)
  File "/home/xiating/.local/lib/python3.5/site-packages/django/utils/decorators.py", line 63, in bound_func
    return func.__get__(self, type(self))(*args2, **kwargs2)
  File "/home/xiating/.local/lib/python3.5/site-packages/django/contrib/admin/options.py", line 1408, in changeform_view
    return self._changeform_view(request, object_id, form_url, extra_context)
  File "/home/xiating/.local/lib/python3.5/site-packages/django/contrib/admin/options.py", line 1448, in _changeform_view
    self.save_model(request, new_object, form, not add)
  File "/home/xiating/dbsec/comp3335_project/comp3335/course/admin.py", line 18, in save_model
    if len(obj.code > 100) or len(obj.name > 100):
TypeError: unorderable types: str() > int()
2017-11-28 17:32:33,830:INFO:request course list for dashboard
2017-11-28 17:32:37,639:WARNING:request course detail failed: course code = COMP1111
2017-11-28 17:32:38,020:INFO:request course list for dashboard
2017-11-28 17:32:41,996:WARNING:request course detail failed: course code = COMP1111
2017-11-28 17:32:42,360:INFO:request course list for dashboard
2017-11-28 18:28:03,362:INFO:request course list for dashboard
2017-11-28 18:28:07,138:WARNING:request course detail failed: course code = COMP1111
2017-11-28 18:28:07,523:INFO:request course list for dashboard
>>>>>>> 2a67c4e6bad57a61d2530edd61b602437dcad8ab
2017-11-28 18:56:43,579:INFO:request course list for dashboard
2017-11-28 18:56:45,338:INFO:request course detail success: course code = COMP1111
2017-11-28 18:56:47,217:INFO:insert message: course code = COMP1111, message = hi
