2017-11-26 01:33:08,569:WARNING:Not Found: /favicon.ico
2017-11-26 01:34:58,576:WARNING:Not Found: /login/
2017-11-26 01:35:43,849:ERROR:Internal Server Error: /
Traceback (most recent call last):
  File "/home/edward/project/lib/python3.6/site-packages/django/core/handlers/exception.py", line 41, in inner
    response = get_response(request)
  File "/home/edward/project/lib/python3.6/site-packages/django/core/handlers/base.py", line 217, in _get_response
    response = self.process_exception_by_middleware(e, request)
  File "/home/edward/project/lib/python3.6/site-packages/django/core/handlers/base.py", line 215, in _get_response
    response = response.render()
  File "/home/edward/project/lib/python3.6/site-packages/django/template/response.py", line 107, in render
    self.content = self.rendered_content
  File "/home/edward/project/lib/python3.6/site-packages/django/template/response.py", line 82, in rendered_content
    template = self.resolve_template(self.template_name)
  File "/home/edward/project/lib/python3.6/site-packages/django/template/response.py", line 64, in resolve_template
    return select_template(template, using=self.using)
  File "/home/edward/project/lib/python3.6/site-packages/django/template/loader.py", line 53, in select_template
    raise TemplateDoesNotExist(', '.join(template_name_list), chain=chain)
django.template.exceptions.TemplateDoesNotExist: welcome/index.html
2017-11-26 01:39:11,789:WARNING:Not Found: /account/login/
2017-11-26 01:39:29,525:WARNING:Not Found: /account/login/
2017-11-27 15:33:11,919:WARNING:Not Found: /favicon.ico
2017-11-27 15:35:31,459:WARNING:Not Found: /account/register/
2017-11-27 15:37:15,435:WARNING:Not Found: /account/register/
2017-11-27 15:37:16,238:WARNING:Not Found: /account/register/
2017-11-27 15:37:16,845:WARNING:Not Found: /account/register/
2017-11-27 15:37:17,575:WARNING:Not Found: /account/register/
2017-11-27 15:37:24,593:WARNING:Not Found: /account/register/
2017-11-27 15:39:10,570:ERROR:Internal Server Error: /account/auth
Traceback (most recent call last):
  File "/home/edward/project/lib/python3.6/site-packages/django/utils/datastructures.py", line 83, in __getitem__
    list_ = super(MultiValueDict, self).__getitem__(key)
KeyError: 'email'

During handling of the above exception, another exception occurred:

Traceback (most recent call last):
  File "/home/edward/project/lib/python3.6/site-packages/django/core/handlers/exception.py", line 41, in inner
    response = get_response(request)
  File "/home/edward/project/lib/python3.6/site-packages/django/core/handlers/base.py", line 187, in _get_response
    response = self.process_exception_by_middleware(e, request)
  File "/home/edward/project/lib/python3.6/site-packages/django/core/handlers/base.py", line 185, in _get_response
    response = wrapped_callback(request, *callback_args, **callback_kwargs)
  File "/home/edward/project/lib/python3.6/site-packages/django/views/decorators/csrf.py", line 58, in wrapped_view
    return view_func(*args, **kwargs)
  File "/home/edward/comp3335/comp3335/account/views.py", line 41, in auth
    username = msg_encrypt(request.POST["email"])
  File "/home/edward/project/lib/python3.6/site-packages/django/utils/datastructures.py", line 85, in __getitem__
    raise MultiValueDictKeyError(repr(key))
django.utils.datastructures.MultiValueDictKeyError: "'email'"
